<?xml version="1.0"?>  
<robot name="limbbot" xmlns:xacro="http://www.ros.org/wiki/xacro">
        
  <link name="base_link"/>

  <joint name="j_phantomx_attachment" type="fixed">
    <parent link="base_link"/>
    <child link="BASE_LIMB"/>
    <origin rpy="0 0 0" xyz="0 0 0.2"/>
  </joint>

  <link name="BASE_LIMB">
    <inertial>
      <origin xyz="0 0 -0.125"/>
      <mass value="10"/>
      <inertia ixx="0.0854" ixy="0.0" ixz="0.0" iyy="0.0854" iyz="0.0" izz="0.0666"/>
    </inertial>
    <visual>
      <origin rpy="0 0 0" xyz="0 0 -0.125"/>
      <geometry>
        <box size="0.2 0.2 0.25"/>
      </geometry>
      <material name="Grey">
        <color rgba="0.20 0.20 0.2 1.0"/>
      </material>
    </visual>
    <collision>
      <origin rpy="0 0 0" xyz="0 0 -0.125"/>
      <geometry>
        <box size="0.2 0.2 0.25"/>a
      </geometry>
    </collision>
  </link>

  <link name="c1_gr">
    <inertial>
      <origin rpy="0 0 0" xyz="0 -0.02633 0"/>
      <mass value="0.024357719"/>
      <inertia ixx="0.0051411124" ixy="-0.00057530255" ixz="-0.000024729049" iyy="0.0081915737" iyz="-0.000019223094" izz="0.0011379812"/>
    </inertial>
    <visual>
      <origin rpy="0 0 0" xyz="0 -0.0252 0"/>
      <geometry>
        <mesh filename="package://moonbot_description/meshes_phantom/connect.STL" scale="1 1 1"/>
      </geometry>
      <material name="Grey">
        <color rgba="0.20 0.20 0.20 1.0"/>
      </material>
    </visual>
    <collision>
      <origin rpy="0 0 0" xyz="0 -0.02633 0"/>
      <geometry>
        <mesh filename="package://moonbot_description/meshes_phantom/connect_coll.STL" scale="1 1 1"/>
      </geometry>
    </collision>
  </link>
  <link name="c2_gr">
    <inertial>
      <origin rpy="0 0 0" xyz="0 -0.02633 0"/>
      <mass value="0.024357719"/>
      <inertia ixx="0.0051411124" ixy="-0.00057530255" ixz="-0.000024729049" iyy="0.0081915737" iyz="-0.000019223094" izz="0.0011379812"/>
    </inertial>
    <visual>
      <origin rpy="0 0 0" xyz="0 -0.0252 0"/>
      <geometry>
        <mesh filename="package://moonbot_description/meshes_phantom/connect.STL" scale="1 1 1"/>
      </geometry>
      <material name="Grey">
        <color rgba="0.20 0.20 0.20 1.0"/>
      </material>
    </visual>
    <collision>
      <origin rpy="0 0 0" xyz="0 -0.02633 0"/>
      <geometry>
        <mesh filename="package://moonbot_description/meshes_phantom/connect_coll.STL" scale="1 1 1"/>
      </geometry>
    </collision>
  </link>
  <link name="thigh_gr">
    <inertial>
      <origin rpy="0 0 0" xyz="0 0 0"/>
      <mass value="0.024357719"/>
      <inertia ixx="0.0051411124" ixy="-0.00057530255" ixz="-0.000024729049" iyy="0.0081915737" iyz="-0.000019223094" izz="0.0011379812"/>
    </inertial>
    <visual>
      <origin rpy="0 0 0" xyz="0 0 0"/>
      <geometry>
        <mesh filename="package://moonbot_description/meshes_phantom/thigh_l.STL" scale="1 1 1"/>
      </geometry>
      <material name="Grey">
        <color rgba="0.20 0.20 0.20 1.0"/>
      </material>
    </visual>
    <collision>
      <origin rpy="0 0 0" xyz="0 0 0"/>
      <geometry>
        <mesh filename="package://moonbot_description/meshes_phantom/thigh_l_coll.STL" scale="1 1 1"/>
      </geometry>
    </collision>
  </link>
  
  <link name="end_gr">
    <inertial>
      <origin rpy="0 0 0" xyz="0 0 0"/>
      <mass value="0.024357719"/>
      <inertia ixx="0.0051411124" ixy="-0.00057530255" ixz="-0.000024729049" iyy="0.0081915737" iyz="-0.000019223094" izz="0.0011379812"/>
    </inertial>
    <visual>
      <origin rpy="0 0 0" xyz="0 0 0"/>
      <geometry>
        <mesh filename="package://moonbot_description/meshes_phantom/tibia_l.STL" scale="1 1 1"/>
      </geometry>
      <material name="Grey">
        <color rgba="0.20 0.20 0.20 1.0"/>
      </material>
    </visual>
    <collision>
      <origin rpy="0 0 0" xyz="0 0 0"/>
      <geometry>
        <box size="0.06 0.06 0.06"/>
      </geometry>
      <surface>
        <friction>
          <ode>
            <mu>0.1</mu>
            <mu2>0.1</mu2>
          </ode>
        </friction>
      </surface>
    </collision>
  </link>

  <joint name="j_c1_gr" type="revolute">
    <parent link="BASE_LIMB"/>
    <child link="c1_gr"/>
    <origin rpy="0.785 4.7123 0.7853981633974483" xyz="0.1 0 -0.05"/>
    <axis xyz="-1 0 0"/>
    <limit effort="2.8" lower="-2.6179939" upper="2.6179939" velocity="5.6548668"/>
  </joint>
  <joint name="j_c2_gr" type="fixed">
    <parent link="c1_gr"/>
    <child link="c2_gr"/>
    <origin rpy="0 1.5704 3.14159" xyz="0 -0.054 0"/>
  </joint>
  <joint name="j_thigh_gr" type="revolute">
    <parent link="c2_gr"/>
    <child link="thigh_gr"/>
    <origin rpy="3.14159 0  0" xyz="0 0 0"/>
    <axis xyz="-1 0 0"/>
    <limit effort="2.8" lower="-2.6179939" upper="2.6179939" velocity="5.6548668"/>
  </joint>
  
  <joint name="j_end_gr" type="revolute">
    <parent link="thigh_gr"/>
    <child link="end_gr"/>
    <origin rpy="0 0 3.14159" xyz="0 -0.0645 -0.0145"/>
    <axis xyz="1 0 0"/>
    <limit effort="2.8" lower="-2.6179939" upper="2.6179939" velocity="5.6548668"/> 
  </joint>


  <ros2_control name="MyRobotSystem2" type="system">
    <hardware>
      <plugin>dynamixel_hardware/DynamixelHardware</plugin>
      <param name="usb_port">/dev/moonbot_RR</param>
      <param name="baud_rate">4000000</param>
      <param name="usb_dummy">false</param>
    </hardware>

    <joint name="j_c1_gr">
      <param name="id">1</param>
      <command_interface name="position">
        <param name="min">-1.57</param>
        <param name="max">1.57</param>
      </command_interface>
      <command_interface name="velocity">
        <param name="min">-5.6548668</param>
        <param name="max">5.6548668</param>
      </command_interface>
      <state_interface name="position"/>
      <state_interface name="velocity"/>
      <state_interface name="effort"/>
    </joint>
    <joint name="j_thigh_gr">
      <param name="id">2</param>
      <command_interface name="position">
        <param name="min">-1.57</param>
        <param name="max">0.756</param>
      </command_interface>
      <command_interface name="velocity">
        <param name="min">-5.6548668</param>
        <param name="max">5.6548668</param>
      </command_interface>
      <state_interface name="position"/>
      <state_interface name="velocity"/>
      <state_interface name="effort"/>
    </joint>
    
    <joint name="j_end_gr">
      <param name="id">3</param>
      <command_interface name="position">
        <param name="min">0</param>
        <param name="max">1.57</param>
      </command_interface>
      <command_interface name="velocity">
        <param name="min">-5.6548668</param>
        <param name="max">5.6548668</param>
      </command_interface>
      <state_interface name="position"/>
      <state_interface name="velocity"/>
      <state_interface name="effort"/>
    </joint>

  </ros2_control>


</robot>
