<?xml version="1.0" ?>
<robot name="MoonbotX" xmlns:xacro="http://www.ros.org/wiki/xacro">
  

  <material name="Grey">
      <color rgba="0.9 0.9 0.98 1" />
  </material>
  <material name="Black">
      <color rgba="0.79216 0.81961 0.93333 1" />
  </material>

  <link name="base_link">
  </link>

  <joint name="moonbot_attachment" type="fixed">
    <parent link="base_link"/>
    <child link="BODY"/>
    <origin rpy="-1.5708 0 0" xyz="0 0 0"/>
  </joint>
  
  <link name="BODY">
    <inertial>
      <origin
        xyz="0.0099766 -0.00010893 0.00095216"
        rpy="0 0 0" />
      <mass
        value="0.84" />
      <inertia
        ixx="0.0017317"
        ixy="6.9779E-10"
        ixz="1.7744E-07"
        iyy="0.0028336"
        iyz="-1.1093E-09"
        izz="0.0017317" />
    </inertial>
    <visual>
      <origin
        xyz="0 0 0"
        rpy="0 0 0" />
      <geometry>
        <mesh
          filename="package://moonbot_description/meshesX/BODY.STL" />
      </geometry>
      <material
        name="">
        <color
          rgba="0.64706 0.61961 0.58431 1" />
      </material>
    </visual>
    <collision>
      <origin
        xyz="0 0 0"
        rpy="0 0 0" />
      <geometry>
        <mesh
          filename="package://moonbot_description/meshesX/BODY.STL" />
      </geometry>
    </collision>
  </link>

  <link name="c1_rf">
    <inertial>
      <origin
        xyz="0.029443 -8.2411E-05 0.00010242"
        rpy="0 0 0" />
      <mass
        value="0.31" />
      <inertia
        ixx="5.0396E-05"
        ixy="-1.345E-09"
        ixz="1.2541E-11"
        iyy="5.7752E-05"
        iyz="-4.0888E-10"
        izz="3.5541E-05" />
    </inertial>
    <visual>
      <origin
        xyz="0 0 0"
        rpy="0 0 0" />
      <geometry>
        <mesh
          filename="package://moonbot_description/meshesX/COXA.STL" />
      </geometry>
      <material
        name="">
        <color
          rgba="0.64706 0.61961 0.58431 1" />
      </material>
    </visual>
    <collision>
      <origin
        xyz="0 0 0"
        rpy="0 0 0" />
      <geometry>
        <mesh
          filename="package://moonbot_description/meshesX/COXA.STL" />
      </geometry>
    </collision>
  </link>

  <link name="thigh_rf">
    <inertial>
      <origin
        xyz="0.064436 0.00087709 -3.2006E-16"
        rpy="0 0 0" />
      <mass
        value="0.1" />
      <inertia
        ixx="6.5997E-05"
        ixy="-5.3873E-21"
        ixz="-1.0696E-11"
        iyy="7.8479E-05"
        iyz="5.2151E-14"
        izz="5.7513E-05" />
    </inertial>
    <visual>
      <origin
        xyz="0 0 0"
        rpy="0 0 0" />
      <geometry>
        <mesh
          filename="package://moonbot_description/meshesX/THIGH.STL" />
      </geometry>
      <material
        name="">
        <color
          rgba="0.64706 0.61961 0.58431 1" />
      </material>
    </visual>
    <collision>
      <origin
        xyz="0 0 0"
        rpy="0 0 0" />
      <geometry>
        <mesh
          filename="package://moonbot_description/meshesX/THIGH.STL" />
      </geometry>
    </collision>
  </link>

  <link name="tibia_rf">
    <inertial>
      <origin
        xyz="0.03718 0.00087779 0.00017544"
        rpy="0 0 0" />
      <mass
        value="0.12" />
      <inertia
        ixx="1.0549E-05"
        ixy="7.2563E-10"
        ixz="1.2917E-09"
        iyy="5.4631E-05"
        iyz="-8.4221E-10"
        izz="5.6057E-05" />
    </inertial>
    <visual>
      <origin
        xyz="0 0 0"
        rpy="0 0 0" />
      <geometry>
        <mesh
          filename="package://moonbot_description/meshesX/TIBIA.STL" />
      </geometry>
      <material
        name="">
        <color
          rgba="0.64706 0.61961 0.58431 1" />
      </material>
    </visual>
    <collision>
      <origin
        xyz="0 0 0"
        rpy="0 0 0" />
      <geometry>
        <mesh
          filename="package://moonbot_description/meshesX/TIBIA.STL" />
      </geometry>
    </collision>
  </link>

  <joint name="j_c1_rf" type="revolute">
    <origin
      xyz="0.13373 -0.00062261 0.12471"
      rpy="1.5708 -0.7854 0" />
    <parent
      link="BODY" />
    <child
      link="c1_rf" />
    <axis
      xyz="0 0 1" />
    <limit
      lower="-1.57"
      upper="1.57"
      effort="2"
      velocity="5" />
  </joint>  

  <joint name="j_thigh_rf" type="revolute">
    <origin
      xyz="0.06455 -0.0003771 -0.0006271"
      rpy="1.5708 0 0" />
    <parent
      link="c1_rf" />
    <child
      link="thigh_rf" />
    <axis
      xyz="0 0 1" />
    <limit
      lower="-1.57"
      upper="1.57"
      effort="2"
      velocity="5" />
  </joint>
  
  <joint name="j_tibia_rf" type="revolute">
    <origin
      xyz="0.129 0 0"
      rpy="0 0 0" />
    <parent
      link="thigh_rf" />
    <child
      link="tibia_rf" />
    <axis
      xyz="0 0 1" />
    <limit
      lower="-1.57"
      upper="1.57"
      effort="2"
      velocity="5" />
  </joint>


  <link name="c1_lf">
    <inertial>
      <origin
        xyz="0.029443 -0.00058239 -0.00010223"
        rpy="0 0 0" />
      <mass
        value="0.31" />
      <inertia
        ixx="5.0396E-05"
        ixy="-1.3183E-09"
        ixz="-1.3254E-11"
        iyy="5.7752E-05"
        iyz="-4.1118E-10"
        izz="3.5541E-05" />
    </inertial>
    <visual>
      <origin
        xyz="0 0 0"
        rpy="0 0 0" />
      <geometry>
        <mesh
          filename="package://moonbot_description/meshesX/COXA.STL" />
      </geometry>
      <material
        name="">
        <color
          rgba="0.64706 0.61961 0.58431 1" />
      </material>
    </visual>
    <collision>
      <origin
        xyz="0 0 0"
        rpy="0 0 0" />
      <geometry>
        <mesh
          filename="package://moonbot_description/meshesX/COXA.STL" />
      </geometry>
    </collision>
  </link>

  <link name="thigh_lf">
    <inertial>
      <origin
        xyz="0.064564 0.00037709 -1.8041E-16"
        rpy="0 0 0" />
      <mass
        value="0.1" />
      <inertia
        ixx="6.5997E-05"
        ixy="4.4533E-19"
        ixz="-1.0696E-11"
        iyy="7.8479E-05"
        iyz="-5.215E-14"
        izz="5.7513E-05" />
    </inertial>
    <visual>
      <origin
        xyz="0 0 0"
        rpy="0 0 0" />
      <geometry>
        <mesh
          filename="package://moonbot_description/meshesX/THIGH.STL" />
      </geometry>
      <material
        name="">
        <color
          rgba="0.64706 0.61961 0.58431 1" />
      </material>
    </visual>
    <collision>
      <origin
        xyz="0 0 0"
        rpy="0 0 0" />
      <geometry>
        <mesh
          filename="package://moonbot_description/meshesX/THIGH.STL" />
      </geometry>
    </collision>
  </link>

  <link name="tibia_lf">
    <inertial>
      <origin
        xyz="0.03718 0.00037641 -0.00017544"
        rpy="0 0 0" />
      <mass
        value="0.12" />
      <inertia
        ixx="1.0549E-05"
        ixy="-7.2517E-10"
        ixz="-1.2927E-09"
        iyy="5.4631E-05"
        iyz="-8.4226E-10"
        izz="5.6057E-05" />
    </inertial>
    <visual>
      <origin
        xyz="0 0 0"
        rpy="0 0 0" />
      <geometry>
        <mesh
          filename="package://moonbot_description/meshesX/TIBIA.STL" />
      </geometry>
      <material
        name="">
        <color
          rgba="0.64706 0.61961 0.58431 1" />
      </material>
    </visual>
    <collision>
      <origin
        xyz="0 0 0"
        rpy="0 0 0" />
      <geometry>
        <mesh
          filename="package://moonbot_description/meshesX/TIBIA.STL" />
      </geometry>
    </collision>
  </link>

  <joint name="j_c1_lf" type="revolute">
    <origin
      xyz="-0.1138 -0.00062261 0.12471"
      rpy="-1.5708 -0.7854 3.1416" />
    <parent
      link="BODY" />
    <child
      link="c1_lf" />
    <axis
      xyz="0 0 1" />
    <limit
      lower="-1.57"
      upper="1.57"
      effort="2"
      velocity="5" />
  </joint>

  <joint name="j_thigh_lf" type="revolute">
    <origin
      xyz="0.06455 -0.0008771 -0.0006271"
      rpy="1.5708 0 0" />
    <parent
      link="c1_lf" />
    <child
      link="thigh_lf" />
    <axis
      xyz="0 0 1" />
    <limit
      lower="-1.57"
      upper="1.57"
      effort="2"
      velocity="5" />
  </joint>

  <joint name="j_tibia_lf" type="revolute">
    <origin
      xyz="0.129 0 0"
      rpy="0 0 0" />
    <parent
      link="thigh_lf" />
    <child
      link="tibia_lf" />
    <axis
      xyz="0 0 1" />
    <limit
      lower="-1.57"
      upper="1.57"
      effort="2"
      velocity="5" />
  </joint> 


  <link name="c1_lr">
    <inertial>
      <origin
        xyz="0.029443 -8.2383E-05 -0.00010224"
        rpy="0 0 0" />
      <mass
        value="0.31" />
      <inertia
        ixx="5.0396E-05"
        ixy="-1.3002E-09"
        ixz="-2.7959E-11"
        iyy="5.7752E-05"
        iyz="-4.0478E-10"
        izz="3.5541E-05" />
    </inertial>
    <visual>
      <origin
        xyz="0 0 0"
        rpy="0 0 0" />
      <geometry>
        <mesh
          filename="package://moonbot_description/meshesX/COXA.STL" />
      </geometry>
      <material
        name="">
        <color
          rgba="0.64706 0.61961 0.58431 1" />
      </material>
    </visual>
    <collision>
      <origin
        xyz="0 0 0"
        rpy="0 0 0" />
      <geometry>
        <mesh
          filename="package://moonbot_description/meshesX/COXA.STL" />
      </geometry>
    </collision>
  </link>

  <link name="thigh_lr">
    <inertial>
      <origin
        xyz="0.0645 0.00087709 -4.8572E-16"
        rpy="0 0 0" />
      <mass
        value="0.1" />
      <inertia
        ixx="5.7513E-05"
        ixy="-5.215E-14"
        ixz="-1.7957E-19"
        iyy="7.8479E-05"
        iyz="-1.1499E-11"
        izz="6.5997E-05" />
    </inertial>
    <visual>
      <origin
        xyz="0 0 0"
        rpy="0 0 0" />
      <geometry>
        <mesh
          filename="package://moonbot_description/meshesX/THIGH.STL" />
      </geometry>
      <material
        name="">
        <color
          rgba="0.64706 0.61961 0.58431 1" />
      </material>
    </visual>
    <collision>
      <origin
        xyz="0 0 0"
        rpy="0 0 0" />
      <geometry>
        <mesh
          filename="package://moonbot_description/meshesX/THIGH.STL" />
      </geometry>
    </collision>
  </link>

  <link name="tibia_lr">
    <inertial>
      <origin
        xyz="0.03718 0.00037753 -0.00017512"
        rpy="0 0 0" />
      <mass
        value="0.12" />
      <inertia
        ixx="1.0549E-05"
        ixy="7.2471E-10"
        ixz="-1.3713E-09"
        iyy="5.4631E-05"
        iyz="-8.4221E-10"
        izz="5.6057E-05" />
    </inertial>
    <visual>
      <origin
        xyz="0 0 0"
        rpy="0 0 0" />
      <geometry>
        <mesh
          filename="package://moonbot_description/meshesX/TIBIA.STL" />
      </geometry>
      <material
        name="">
        <color
          rgba="0.64706 0.61961 0.58431 1" />
      </material>
    </visual>
    <collision>
      <origin
        xyz="0 0 0"
        rpy="0 0 0" />
      <geometry>
        <mesh
          filename="package://moonbot_description/meshesX/TIBIA.STL" />
      </geometry>
    </collision>
  </link>

  <joint name="j_c1_lr" type="revolute">
    <origin
      xyz="-0.11380255065902 -0.000622612263592514 -0.122826956051948"
      rpy="-1.57079632679487 0.785398163397452 -3.14159265358979" />
    <parent
      link="BODY" />
    <child
      link="c1_lr" />
    <axis
      xyz="0 0 1" />
    <limit
      lower="-1.57"
      upper="1.57"
      effort="2"
      velocity="5" />
  </joint>

  <joint name="j_thigh_lr" type="revolute">
    <origin
      xyz="0.06455 0.0008771 -0.0006271"
      rpy="1.5708 0 0" />
    <parent
      link="c1_lr" />
    <child
      link="thigh_lr" />
    <axis
      xyz="0 0 1" />
    <limit
      lower="-1.57"
      upper="1.57"
      effort="2"
      velocity="5" />
  </joint>
  
  <joint name="j_tibia_lr" type="revolute">
    <origin
      xyz="0.129 0 0"
      rpy="0 0 0" />
    <parent
      link="thigh_lr" />
    <child
      link="tibia_lr" />
    <axis
      xyz="0 0 1" />
    <limit
      lower="-1.57"
      upper="1.57"
      effort="2"
      velocity="5" />
  </joint>


  <link name="c1_rr">
    <inertial>
      <origin
        xyz="0.029443 0.00058239 0.00010223"
        rpy="0 0 0" />
      <mass
        value="0.31" />
      <inertia
        ixx="5.0396E-05"
        ixy="1.3177E-09"
        ixz="1.1591E-11"
        iyy="5.7752E-05"
        iyz="-4.155E-10"
        izz="3.5541E-05" />
    </inertial>
    <visual>
      <origin
        xyz="0 0 0"
        rpy="0 0 0" />
      <geometry>
        <mesh
          filename="package://moonbot_description/meshesX/COXA.STL" />
      </geometry>
      <material
        name="">
        <color
          rgba="0.64706 0.61961 0.58431 1" />
      </material>
    </visual>
    <collision>
      <origin
        xyz="0 0 0"
        rpy="0 0 0" />
      <geometry>
        <mesh
          filename="package://moonbot_description/meshesX/COXA.STL" />
      </geometry>
    </collision>
  </link>

  <link name="thigh_rr">
    <inertial>
      <origin
        xyz="0.0645 0.00087709 -4.8572E-16"
        rpy="0 0 0" />
      <mass
        value="0.1" />
      <inertia
        ixx="6.5997E-05"
        ixy="1.6164E-20"
        ixz="9.2026E-10"
        iyy="7.8479E-05"
        iyz="6.0862E-19"
        izz="5.7513E-05" />
    </inertial>
    <visual>
      <origin
        xyz="0 0 0"
        rpy="0 0 0" />
      <geometry>
        <mesh
          filename="package://moonbot_description/meshesX/THIGH.STL" />
      </geometry>
      <material
        name="">
        <color
          rgba="0.64706 0.61961 0.58431 1" />
      </material>
    </visual>
    <collision>
      <origin
        xyz="0 0 0"
        rpy="0 0 0" />
      <geometry>
        <mesh
          filename="package://moonbot_description/meshesX/THIGH.STL" />
      </geometry>
    </collision>
  </link>

  <link name="tibia_rr">
    <inertial>
      <origin
        xyz="0.03718 0.00087779 0.00017544"
        rpy="0 0 0" />
      <mass
        value="0.12" />
      <inertia
        ixx="1.0549E-05"
        ixy="7.2506E-10"
        ixz="1.2925E-09"
        iyy="5.4631E-05"
        iyz="-8.4227E-10"
        izz="5.6057E-05" />
    </inertial>
    <visual>
      <origin
        xyz="0 0 0"
        rpy="0 0 0" />
      <geometry>
        <mesh
          filename="package://moonbot_description/meshesX/TIBIA.STL" />
      </geometry>
      <material
        name="">
        <color
          rgba="0.64706 0.61961 0.58431 1" />
      </material>
    </visual>
    <collision>
      <origin
        xyz="0 0 0"
        rpy="0 0 0" />
      <geometry>
        <mesh
          filename="package://moonbot_description/meshesX/TIBIA.STL" />
      </geometry>
    </collision>
  </link>

  <joint name="j_c1_rr" type="revolute">
    <origin
      xyz="0.13373 -0.00062261 -0.12283"
      rpy="1.5708 0.7854 0" />
    <parent
      link="BODY" />
    <child
      link="c1_rr" />
    <axis
      xyz="0 0 1" />
    <limit
      lower="-1.57"
      upper="1.57"
      effort="2"
      velocity="5" />
  </joint>

  <joint name="j_thigh_rr" type="revolute">
    <origin
      xyz="0.06455 0.0008771 -0.0006271"
      rpy="1.5708 0 0" />
    <parent
      link="c1_rr" />
    <child
      link="thigh_rr" />
    <axis
      xyz="0 0 1" />
    <limit
      lower="-1.57"
      upper="1.57"
      effort="2"
      velocity="5" />
  </joint>

  <joint name="j_tibia_rr" type="revolute">
    <origin
      xyz="0.129 0 0"
      rpy="0 0 0" />
    <parent
      link="thigh_rr" />
    <child
      link="tibia_rr" />
    <axis
      xyz="0 0 1" />
    <limit
      lower="-1.57"
      upper="1.57"
      effort="2"
      velocity="5" />
  </joint> 

  <gazebo reference="BODY">
    <material>Gazebo/DarkGrey</material>
  </gazebo>

  <gazebo reference="c1_rf">
    <material>Gazebo/White</material>
  </gazebo>
  <gazebo reference="thigh_rf">
    <material>Gazebo/DarkGrey</material>
  </gazebo>
  <gazebo reference="tibia_rf">
    <material>Gazebo/DarkGrey</material>
  </gazebo>

  <gazebo reference="c1_lf">
    <material>Gazebo/White</material>
  </gazebo>
  <gazebo reference="thigh_lf">
    <material>Gazebo/DarkGrey</material>
  </gazebo>
  <gazebo reference="tibia_lf">
    <material>Gazebo/DarkGrey</material>
  </gazebo>

  <gazebo reference="c1_lr">
    <material>Gazebo/White</material>
  </gazebo>
  <gazebo reference="thigh_lr">
    <material>Gazebo/DarkGrey</material>
  </gazebo>
  <gazebo reference="tibia_lr">
    <material>Gazebo/DarkGrey</material>
  </gazebo>

  <gazebo reference="c1_rr">
    <material>Gazebo/White</material>
  </gazebo>
  <gazebo reference="thigh_rr">
    <material>Gazebo/DarkGrey</material>
  </gazebo>
  <gazebo reference="tibia_rr">
    <material>Gazebo/DarkGrey</material>
  </gazebo>



  <ros2_control name="MyRobotSystem" type="system">
    <hardware>
      <plugin>gazebo_ros2_control/GazeboSystem</plugin>
    </hardware>
    
    <joint name="j_c1_rf">
      <command_interface name="position">
        <param name="min">-1.57</param>
        <param name="max">1.57</param>
      </command_interface>
      <command_interface name="velocity">
        <param name="min">-5.6548668</param>
        <param name="max">5.6548668</param>
      </command_interface>
      <command_interface name="effort">
        <param name="min">-15.0</param>
        <param name="max">15.0</param>
      </command_interface>
      <state_interface name="position"/>
      <state_interface name="velocity"/>
      <state_interface name="effort"/>
    </joint>

    <joint name="j_thigh_rf">
      <command_interface name="position">
        <param name="min">-1.57</param>
        <param name="max">0.756</param>
      </command_interface>
      <command_interface name="velocity">
        <param name="min">-5.6548668</param>
        <param name="max">5.6548668</param>
      </command_interface>
      <command_interface name="effort">
        <param name="min">-15.0</param>
        <param name="max">15.0</param>
      </command_interface>
      <state_interface name="position"/>
      <state_interface name="velocity"/>
      <state_interface name="effort"/>
    </joint>

    <joint name="j_tibia_rf">
      <command_interface name="position">
        <param name="min">-1.57</param>
        <param name="max">1.57</param>
      </command_interface>
      <command_interface name="velocity">
        <param name="min">-5.6548668</param>
        <param name="max">5.6548668</param>
      </command_interface>
      <command_interface name="effort">
        <param name="min">-15.0</param>
        <param name="max">15.0</param>
      </command_interface>
      <state_interface name="position"/>
      <state_interface name="velocity"/>
      <state_interface name="effort"/>
    </joint>

    <joint name="j_c1_lf">
      <command_interface name="position">
        <param name="min">-1.57</param>
        <param name="max">1.57</param>
      </command_interface>
      <command_interface name="velocity">
        <param name="min">-5.6548668</param>
        <param name="max">5.6548668</param>
      </command_interface>
      <command_interface name="effort">
        <param name="min">-15.0</param>
        <param name="max">15.0</param>
      </command_interface>
      <state_interface name="position"/>
      <state_interface name="velocity"/>
      <state_interface name="effort"/>
    </joint>

    <joint name="j_thigh_lf">
      <command_interface name="position">
        <param name="min">-1.57</param>
        <param name="max">0.756</param>
      </command_interface>
      <command_interface name="velocity">
        <param name="min">-5.6548668</param>
        <param name="max">5.6548668</param>
      </command_interface>
      <command_interface name="effort">
        <param name="min">-15.0</param>
        <param name="max">15.0</param>
      </command_interface>
      <state_interface name="position"/>
      <state_interface name="velocity"/>
      <state_interface name="effort"/>
    </joint>

    <joint name="j_tibia_lf">
      <command_interface name="position">
        <param name="min">-1.57</param>
        <param name="max">1.57</param>
      </command_interface>
      <command_interface name="velocity">
        <param name="min">-5.6548668</param>
        <param name="max">5.6548668</param>
      </command_interface>
      <command_interface name="effort">
        <param name="min">-15.0</param>
        <param name="max">15.0</param>
      </command_interface>
      <state_interface name="position"/>
      <state_interface name="velocity"/>
      <state_interface name="effort"/>
    </joint>

    <joint name="j_c1_lr">
      <command_interface name="position">
        <param name="min">-1.57</param>
        <param name="max">1.57</param>
      </command_interface>
      <command_interface name="velocity">
        <param name="min">-5.6548668</param>
        <param name="max">5.6548668</param>
      </command_interface>
      <command_interface name="effort">
        <param name="min">-15.0</param>
        <param name="max">15.0</param>
      </command_interface>
      <state_interface name="position"/>
      <state_interface name="velocity"/>
      <state_interface name="effort"/>
    </joint>

    <joint name="j_thigh_lr">
      <command_interface name="position">
        <param name="min">-1.57</param>
        <param name="max">0.756</param>
      </command_interface>
      <command_interface name="velocity">
        <param name="min">-5.6548668</param>
        <param name="max">5.6548668</param>
      </command_interface>
      <command_interface name="effort">
        <param name="min">-15.0</param>
        <param name="max">15.0</param>
      </command_interface>
      <state_interface name="position"/>
      <state_interface name="velocity"/>
      <state_interface name="effort"/>
    </joint>

    <joint name="j_tibia_lr">
      <command_interface name="position">
        <param name="min">-1.57</param>
        <param name="max">1.57</param>
      </command_interface>
      <command_interface name="velocity">
        <param name="min">-5.6548668</param>
        <param name="max">5.6548668</param>
      </command_interface>
      <command_interface name="effort">
        <param name="min">-15.0</param>
        <param name="max">15.0</param>
      </command_interface>
      <state_interface name="position"/>
      <state_interface name="velocity"/>
      <state_interface name="effort"/>
    </joint>

    <joint name="j_c1_rr">
      <command_interface name="position">
        <param name="min">-1.57</param>
        <param name="max">1.57</param>
      </command_interface>
      <command_interface name="velocity">
        <param name="min">-5.6548668</param>
        <param name="max">5.6548668</param>
      </command_interface>
      <command_interface name="effort">
        <param name="min">-15.0</param>
        <param name="max">15.0</param>
      </command_interface>
      <state_interface name="position"/>
      <state_interface name="velocity"/>
      <state_interface name="effort"/>
    </joint>

    <joint name="j_thigh_rr">
      <command_interface name="position">
        <param name="min">-1.57</param>
        <param name="max">0.756</param>
      </command_interface>
      <command_interface name="velocity">
        <param name="min">-5.6548668</param>
        <param name="max">5.6548668</param>
      </command_interface>
      <command_interface name="effort">
        <param name="min">-15.0</param>
        <param name="max">15.0</param>
      </command_interface>
      <state_interface name="position"/>
      <state_interface name="velocity"/>
      <state_interface name="effort"/>
    </joint>

    <joint name="j_tibia_rr">
      <command_interface name="position">
        <param name="min">-1.57</param>
        <param name="max">1.57</param>
      </command_interface>
      <command_interface name="velocity">
        <param name="min">-5.6548668</param>
        <param name="max">5.6548668</param>
      </command_interface>
      <command_interface name="effort">
        <param name="min">-15.0</param>
        <param name="max">15.0</param>
      </command_interface>
      <state_interface name="position"/>
      <state_interface name="velocity"/>
      <state_interface name="effort"/>
    </joint>

  </ros2_control>

  <!-- Gazebo's ros2_control plugin  -->
  <gazebo>
    <plugin filename="libgazebo_ros2_control.so" name="gazebo_ros2_control">
      <robot_sim_type>gazebo_ros2_control/GazeboSystem</robot_sim_type>
      <robot_param>robot_description</robot_param>
      <robot_param_node>robot_state_publisher_node</robot_param_node>
      <parameters>$(find moonbot_control)/config/moonbot_config.yaml</parameters>
    </plugin>
  </gazebo> 





</robot>