<?xml version="1.0" encoding="utf-8"?>

<robot
  name="Moonbot_1_urdf"
  xmlns:xacro="http://www.ros.org/wiki/xacro">
  <link
    name="base_link">
    <inertial>
      <origin
        xyz="4.4525E-06 -1.372E-05 0.015651"
        rpy="0 0 0" />
      <mass
        value="1.7613" />
      <inertia
        ixx="0.0022157"
        ixy="1.9729E-07"
        ixz="6.2687E-11"
        iyy="0.0022117"
        iyz="-1.9316E-10"
        izz="0.0037074" />
    </inertial>
    <visual>
      <origin
        xyz="0 0 0"
        rpy="0 0 0" />
      <geometry>
        <mesh
          filename="package://moonbot_description/meshes/base_link.STL" />
      </geometry>
      <material
        name="">
        <color
          rgba="0.64706 0.61961 0.58431 1" />
      </material>
    </visual>
    <collision>
      <origin
        xyz="0 0 0"
        rpy="0 0 0" />
      <geometry>
        <mesh
          filename="package://moonbot_description/meshes/base_link.STL" />
      </geometry>
    </collision>
  </link>
  <link
    name="Leg1_Link1">
    <inertial>
      <origin
        xyz="-0.16164 -0.16206 0.0078727"
        rpy="0 0 0" />
      <mass
        value="0.19524" />
      <inertia
        ixx="0.00013212"
        ixy="-2.569E-05"
        ixz="3.8551E-10"
        iyy="0.00013211"
        iyz="4.1271E-10"
        izz="0.00012874" />
    </inertial>
    <visual>
      <origin
        xyz="0 0 0"
        rpy="0 0 0" />
      <geometry>
        <mesh
          filename="package://moonbot_description/meshes/Leg1_Link1.STL" />
      </geometry>
      <material
        name="">
        <color
          rgba="0.64706 0.61961 0.58431 1" />
      </material>
    </visual>
    <collision>
      <origin
        xyz="0 0 0"
        rpy="0 0 0" />
      <geometry>
        <mesh
          filename="package://moonbot_description/meshes/Leg1_Link1.STL" />
      </geometry>
    </collision>
  </link>
  <joint
    name="Leg1_Joint1"
    type="revolute">
    <origin
      xyz="0 0 0"
      rpy="0 0 0" />
    <parent
      link="base_link" />
    <child
      link="Leg1_Link1" />
    <axis
      xyz="0 0 -1" />
    <limit
      lower="-1.57"
      upper="1.57"
      effort="200"
      velocity="3" />
  </joint>
  <link
    name="Leg1_Link2">
    <inertial>
      <origin
        xyz="-0.20029 -0.19993 -0.0487"
        rpy="0 0 0" />
      <mass
        value="0.2225" />
      <inertia
        ixx="0.00024185"
        ixy="1.6469E-05"
        ixz="2.7889E-10"
        iyy="0.00024185"
        iyz="-2.7889E-10"
        izz="0.00016006" />
    </inertial>
    <visual>
      <origin
        xyz="0 0 0"
        rpy="0 0 0" />
      <geometry>
        <mesh
          filename="package://moonbot_description/meshes/Leg1_Link2.STL" />
      </geometry>
      <material
        name="">
        <color
          rgba="0.64706 0.61961 0.58431 1" />
      </material>
    </visual>
    <collision>
      <origin
        xyz="0 0 0"
        rpy="0 0 0" />
      <geometry>
        <mesh
          filename="package://moonbot_description/meshes/Leg1_Link2.STL" />
      </geometry>
    </collision>
  </link>
  <joint
    name="Leg1_Joint2"
    type="revolute">
    <origin
      xyz="0 0 0"
      rpy="0 0 0" />
    <parent
      link="Leg1_Link1" />
    <child
      link="Leg1_Link2" />
    <axis
      xyz="0.70711 -0.70711 0" />
    <limit
      lower="-1.57"
      upper="1.57"
      effort="200"
      velocity="3" />
  </joint>
  <link
    name="Leg1_Link3">
    <inertial>
      <origin
        xyz="-0.19985 -0.20037 -0.14553"
        rpy="0 0 0" />
      <mass
        value="0.14207" />
      <inertia
        ixx="4.5915E-05"
        ixy="-5.5477E-06"
        ixz="-6.9185E-10"
        iyy="4.5915E-05"
        iyz="1.1922E-09"
        izz="5.1594E-05" />
    </inertial>
    <visual>
      <origin
        xyz="0 0 0"
        rpy="0 0 0" />
      <geometry>
        <mesh
          filename="package://moonbot_description/meshes/Leg1_Link3.STL" />
      </geometry>
      <material
        name="">
        <color
          rgba="0.64706 0.61961 0.58431 1" />
      </material>
    </visual>
    <collision>
      <origin
        xyz="0 0 0"
        rpy="0 0 0" />
      <geometry>
        <mesh
          filename="package://moonbot_description/meshes/Leg1_Link3.STL" />
      </geometry>
    </collision>
  </link>
  <joint
    name="Leg1_Joint3"
    type="revolute">
    <origin
      xyz="0 0 0"
      rpy="0 0 0" />
    <parent
      link="Leg1_Link2" />
    <child
      link="Leg1_Link3" />
    <axis
      xyz="0.70711 -0.70711 0" />
    <limit
      lower="-1.57"
      upper="1.57"
      effort="200"
      velocity="3" />
  </joint>
  <link
    name="Leg2_Link1">
    <inertial>
      <origin
        xyz="-0.16206 0.16164 0.0078727"
        rpy="0 0 0" />
      <mass
        value="0.19524" />
      <inertia
        ixx="0.00013211"
        ixy="2.569E-05"
        ixz="4.1271E-10"
        iyy="0.00013212"
        iyz="-3.8551E-10"
        izz="0.00012874" />
    </inertial>
    <visual>
      <origin
        xyz="0 0 0"
        rpy="0 0 0" />
      <geometry>
        <mesh
          filename="package://moonbot_description/meshes/Leg2_Link1.STL" />
      </geometry>
      <material
        name="">
        <color
          rgba="0.64706 0.61961 0.58431 1" />
      </material>
    </visual>
    <collision>
      <origin
        xyz="0 0 0"
        rpy="0 0 0" />
      <geometry>
        <mesh
          filename="package://moonbot_description/meshes/Leg2_Link1.STL" />
      </geometry>
    </collision>
  </link>
  <joint
    name="Leg2_Joint1"
    type="revolute">
    <origin
      xyz="0 0 0"
      rpy="0 0 0" />
    <parent
      link="base_link" />
    <child
      link="Leg2_Link1" />
    <axis
      xyz="0 0 -1" />
    <limit
      lower="-1.57"
      upper="1.57"
      effort="200"
      velocity="3" />
  </joint>
  <link
    name="Leg2_Link2">
    <inertial>
      <origin
        xyz="-0.19993 0.20029 -0.0487"
        rpy="0 0 0" />
      <mass
        value="0.2225" />
      <inertia
        ixx="0.00024185"
        ixy="-1.6469E-05"
        ixz="-3.0519E-10"
        iyy="0.00024185"
        iyz="3.0519E-10"
        izz="0.00016006" />
    </inertial>
    <visual>
      <origin
        xyz="0 0 0"
        rpy="0 0 0" />
      <geometry>
        <mesh
          filename="package://moonbot_description/meshes/Leg2_Link2.STL" />
      </geometry>
      <material
        name="">
        <color
          rgba="0.64706 0.61961 0.58431 1" />
      </material>
    </visual>
    <collision>
      <origin
        xyz="0 0 0"
        rpy="0 0 0" />
      <geometry>
        <mesh
          filename="package://moonbot_description/meshes/Leg2_Link2.STL" />
      </geometry>
    </collision>
  </link>
  <joint
    name="Leg2_Joint2"
    type="revolute">
    <origin
      xyz="0 0 0"
      rpy="0 0 0" />
    <parent
      link="Leg2_Link1" />
    <child
      link="Leg2_Link2" />
    <axis
      xyz="0.70711 0.70711 0" />
    <limit
      lower="-1.57"
      upper="1.57"
      effort="200"
      velocity="3" />
  </joint>
  <link
    name="Leg2_Link3">
    <inertial>
      <origin
        xyz="-0.20037 0.19985 -0.14553"
        rpy="0 0 0" />
      <mass
        value="0.14207" />
      <inertia
        ixx="4.5915E-05"
        ixy="5.5477E-06"
        ixz="1.1923E-09"
        iyy="4.5915E-05"
        iyz="6.9184E-10"
        izz="5.1594E-05" />
    </inertial>
    <visual>
      <origin
        xyz="0 0 0"
        rpy="0 0 0" />
      <geometry>
        <mesh
          filename="package://moonbot_description/meshes/Leg2_Link3.STL" />
      </geometry>
      <material
        name="">
        <color
          rgba="0.64706 0.61961 0.58431 1" />
      </material>
    </visual>
    <collision>
      <origin
        xyz="0 0 0"
        rpy="0 0 0" />
      <geometry>
        <mesh
          filename="package://moonbot_description/meshes/Leg2_Link3.STL" />
      </geometry>
    </collision>
  </link>
  <joint
    name="Leg2_joint3"
    type="revolute">
    <origin
      xyz="0 0 0"
      rpy="0 0 0" />
    <parent
      link="Leg2_Link2" />
    <child
      link="Leg2_Link3" />
    <axis
      xyz="0.70711 0.70711 0" />
    <limit
      lower="-1.57"
      upper="1.57"
      effort="200"
      velocity="3" />
  </joint>
  <link
    name="Leg3_Link1">
    <inertial>
      <origin
        xyz="0.16181 -0.16189 0.0078731"
        rpy="0 0 0" />
      <mass
        value="0.19524" />
      <inertia
        ixx="0.00013212"
        ixy="2.569E-05"
        ixz="3.8551E-10"
        iyy="0.00013211"
        iyz="-4.1271E-10"
        izz="0.00012874" />
    </inertial>
    <visual>
      <origin
        xyz="0 0 0"
        rpy="0 0 0" />
      <geometry>
        <mesh
          filename="package://moonbot_description/meshes/Leg3_Link1.STL" />
      </geometry>
      <material
        name="">
        <color
          rgba="0.64706 0.61961 0.58431 1" />
      </material>
    </visual>
    <collision>
      <origin
        xyz="0 0 0"
        rpy="0 0 0" />
      <geometry>
        <mesh
          filename="package://moonbot_description/meshes/Leg3_Link1.STL" />
      </geometry>
    </collision>
  </link>
  <joint
    name="Leg3_Joint1"
    type="revolute">
    <origin
      xyz="0 0 0"
      rpy="0 0 0" />
    <parent
      link="base_link" />
    <child
      link="Leg3_Link1" />
    <axis
      xyz="0 0 -1" />
    <limit
      lower="-1.57"
      upper="1.57"
      effort="200"
      velocity="3" />
  </joint>
  <link
    name="Leg3_Link2">
    <inertial>
      <origin
        xyz="0.20046 -0.19976 -0.0487"
        rpy="0 0 0" />
      <mass
        value="0.2225" />
      <inertia
        ixx="0.00024185"
        ixy="-1.6469E-05"
        ixz="-3.0519E-10"
        iyy="0.00024185"
        iyz="3.0519E-10"
        izz="0.00016006" />
    </inertial>
    <visual>
      <origin
        xyz="0 0 0"
        rpy="0 0 0" />
      <geometry>
        <mesh
          filename="package://moonbot_description/meshes/Leg3_Link2.STL" />
      </geometry>
      <material
        name="">
        <color
          rgba="0.64706 0.61961 0.58431 1" />
      </material>
    </visual>
    <collision>
      <origin
        xyz="0 0 0"
        rpy="0 0 0" />
      <geometry>
        <mesh
          filename="package://moonbot_description/meshes/Leg3_Link2.STL" />
      </geometry>
    </collision>
  </link>
  <joint
    name="Leg3_Joint2"
    type="revolute">
    <origin
      xyz="0 0 0"
      rpy="0 0 0" />
    <parent
      link="Leg3_Link1" />
    <child
      link="Leg3_Link2" />
    <axis
      xyz="0.70711 0.70711 0" />
    <limit
      lower="-1.57"
      upper="1.57"
      effort="200"
      velocity="3" />
  </joint>
  <link
    name="Leg3_Link3">
    <inertial>
      <origin
        xyz="0.2009 -0.19932 -0.14553"
        rpy="0 0 0" />
      <mass
        value="0.14207" />
      <inertia
        ixx="4.5915E-05"
        ixy="5.5477E-06"
        ixz="-1.1923E-09"
        iyy="4.5915E-05"
        iyz="-6.9184E-10"
        izz="5.1594E-05" />
    </inertial>
    <visual>
      <origin
        xyz="0 0 0"
        rpy="0 0 0" />
      <geometry>
        <mesh
          filename="package://moonbot_description/meshes/Leg3_Link3.STL" />
      </geometry>
      <material
        name="">
        <color
          rgba="0.64706 0.61961 0.58431 1" />
      </material>
    </visual>
    <collision>
      <origin
        xyz="0 0 0"
        rpy="0 0 0" />
      <geometry>
        <mesh
          filename="package://moonbot_description/meshes/Leg3_Link3.STL" />
      </geometry>
    </collision>
  </link>
  <joint
    name="Leg3_Joint3"
    type="revolute">
    <origin
      xyz="0 0 0"
      rpy="0 0 0" />
    <parent
      link="Leg3_Link2" />
    <child
      link="Leg3_Link3" />
    <axis
      xyz="0.70711 0.70711 0" />
    <limit
      lower="-1.57"
      upper="1.57"
      effort="200"
      velocity="3" />
  </joint>
  <link
    name="Leg4_Link1">
    <inertial>
      <origin
        xyz="4.4525E-06 -1.372E-05 0.015651"
        rpy="0 0 0" />
      <mass
        value="1.7613" />
      <inertia
        ixx="0.0022157"
        ixy="1.9729E-07"
        ixz="6.2687E-11"
        iyy="0.0022117"
        iyz="-1.9316E-10"
        izz="0.0037074" />
    </inertial>
    <visual>
      <origin
        xyz="0 0 0"
        rpy="0 0 0" />
      <geometry>
        <mesh
          filename="package://moonbot_description/meshes/Leg4_Link1.STL" />
      </geometry>
      <material
        name="">
        <color
          rgba="0.64706 0.61961 0.58431 1" />
      </material>
    </visual>
    <collision>
      <origin
        xyz="0 0 0"
        rpy="0 0 0" />
      <geometry>
        <mesh
          filename="package://moonbot_description/meshes/Leg4_Link1.STL" />
      </geometry>
    </collision>
  </link>
  <joint
    name="Leg4_Joint1"
    type="revolute">
    <origin
      xyz="0 0 0"
      rpy="0 0 0" />
    <parent
      link="base_link" />
    <child
      link="Leg4_Link1" />
    <axis
      xyz="0 0 -1" />
    <limit
      lower="-1.57"
      upper="1.57"
      effort="200"
      velocity="3" />
  </joint>
  <link
    name="Leg4_Link2">
    <inertial>
      <origin
        xyz="0.20029 0.19993 -0.0487"
        rpy="0 0 0" />
      <mass
        value="0.2225" />
      <inertia
        ixx="0.00024185"
        ixy="1.6469E-05"
        ixz="-3.0519E-10"
        iyy="0.00024185"
        iyz="-3.0519E-10"
        izz="0.00016006" />
    </inertial>
    <visual>
      <origin
        xyz="0 0 0"
        rpy="0 0 0" />
      <geometry>
        <mesh
          filename="package://moonbot_description/meshes/Leg4_Link2.STL" />
      </geometry>
      <material
        name="">
        <color
          rgba="0.64706 0.61961 0.58431 1" />
      </material>
    </visual>
    <collision>
      <origin
        xyz="0 0 0"
        rpy="0 0 0" />
      <geometry>
        <mesh
          filename="package://moonbot_description/meshes/Leg4_Link2.STL" />
      </geometry>
    </collision>
  </link>
  <joint
    name="LEg4_Joint2"
    type="revolute">
    <origin
      xyz="0 0 0"
      rpy="0 0 0" />
    <parent
      link="Leg4_Link1" />
    <child
      link="Leg4_Link2" />
    <axis
      xyz="-0.70711 0.70711 0" />
    <limit
      lower="-1.57"
      upper="1.57"
      effort="200"
      velocity="3" />
  </joint>
  <link
    name="Leg4_Link3">
    <inertial>
      <origin
        xyz="0.19985 0.20037 -0.14553"
        rpy="0 0 0" />
      <mass
        value="0.14207" />
      <inertia
        ixx="4.5915E-05"
        ixy="-5.5477E-06"
        ixz="6.9186E-10"
        iyy="4.5915E-05"
        iyz="-1.1923E-09"
        izz="5.1594E-05" />
    </inertial>
    <visual>
      <origin
        xyz="0 0 0"
        rpy="0 0 0" />
      <geometry>
        <mesh
          filename="package://moonbot_description/meshes/Leg4_Link3.STL" />
      </geometry>
      <material
        name="">
        <color
          rgba="0.64706 0.61961 0.58431 1" />
      </material>
    </visual>
    <collision>
      <origin
        xyz="0 0 0"
        rpy="0 0 0" />
      <geometry>
        <mesh
          filename="package://moonbot_description/meshes/Leg4_Link3.STL" />
      </geometry>
    </collision>
  </link>
  <joint
    name="Leg4_Joint3"
    type="revolute">
    <origin
      xyz="0 0 0"
      rpy="0 0 0" />
    <parent
      link="Leg4_Link2" />
    <child
      link="Leg4_Link3" />
    <axis
      xyz="-0.70711 0.70711 0" />
    <limit
      lower="-1.57"
      upper="1.57"
      effort="200"
      velocity="3" />
  </joint>
</robot>