<?xml version="1.0" encoding="utf-8"?>
<!-- This URDF was automatically created by SolidWorks to URDF Exporter! Originally created by Stephen Brawner (brawner@gmail.com) 
     Commit Version: 1.6.0-4-g7f85cfe  Build Version: 1.6.7995.38578
     For more information, please see http://wiki.ros.org/sw_urdf_exporter -->
<robot
  name="wwww_urdf">
  <link
    name="base_link">
    <inertial>
      <origin
        xyz="0.14217 0.17203 0.27483"
        rpy="0 0 0" />
      <mass
        value="1.8502" />
      <inertia
        ixx="0.0021622"
        ixy="-4.6497E-12"
        ixz="2.6583E-09"
        iyy="0.0021628"
        iyz="-6.4325E-09"
        izz="0.0031349" />
    </inertial>
    <visual>
      <origin
        xyz="0 0 0"
        rpy="0 0 0" />
      <geometry>
        <mesh
          filename="package://wwww_urdf/meshes/base_link.STL" />
      </geometry>
      <material
        name="">
        <color
          rgba="0.79216 0.81961 0.93333 1" />
      </material>
    </visual>
    <collision>
      <origin
        xyz="0 0 0"
        rpy="0 0 0" />
      <geometry>
        <mesh
          filename="package://wwww_urdf/meshes/base_link.STL" />
      </geometry>
    </collision>
  </link>
  <link
    name="Leg1_Coxa">
    <inertial>
      <origin
        xyz="0.029251 -0.00033242 0.035561"
        rpy="0 0 0" />
      <mass
        value="0.10502" />
      <inertia
        ixx="5.0395E-05"
        ixy="1.3468E-09"
        ixz="8.0078E-08"
        iyy="5.7752E-05"
        iyz="4.2049E-10"
        izz="3.5542E-05" />
    </inertial>
    <visual>
      <origin
        xyz="0 0 0"
        rpy="0 0 0" />
      <geometry>
        <mesh
          filename="package://wwww_urdf/meshes/Leg1_Coxa.STL" />
      </geometry>
      <material
        name="">
        <color
          rgba="0.79216 0.81961 0.93333 1" />
      </material>
    </visual>
    <collision>
      <origin
        xyz="0 0 0"
        rpy="0 0 0" />
      <geometry>
        <mesh
          filename="package://wwww_urdf/meshes/Leg1_Coxa.STL" />
      </geometry>
    </collision>
  </link>
  <joint
    name="Leg1_joint1"
    type="revolute">
    <origin
      xyz="0.075436 -0.24008 0.33384"
      rpy="1.56 -1.1089 0.012099" />
    <parent
      link="base_link" />
    <child
      link="Leg1_Coxa" />
    <axis
      xyz="0.0053918 0 -0.99999" />
    <limit
      lower="0"
      upper="0"
      effort="0"
      velocity="6.387" />
  </joint>
  <link
    name="Leg1_Femur">
    <inertial>
      <origin
        xyz="-0.05592 0.0006271 -0.032144"
        rpy="0 0 0" />
      <mass
        value="0.094729" />
      <inertia
        ixx="6.9097E-05"
        ixy="-8.1639E-10"
        ixz="-5.3933E-06"
        iyy="5.7513E-05"
        iyz="-4.6925E-10"
        izz="7.5379E-05" />
    </inertial>
    <visual>
      <origin
        xyz="0 0 0"
        rpy="0 0 0" />
      <geometry>
        <mesh
          filename="package://wwww_urdf/meshes/Leg1_Femur.STL" />
      </geometry>
      <material
        name="">
        <color
          rgba="0.79216 0.81961 0.93333 1" />
      </material>
    </visual>
    <collision>
      <origin
        xyz="0 0 0"
        rpy="0 0 0" />
      <geometry>
        <mesh
          filename="package://wwww_urdf/meshes/Leg1_Femur.STL" />
      </geometry>
    </collision>
  </link>
  <joint
    name="Leg1_joint2"
    type="revolute">
    <origin
      xyz="0.064357 0 0.035898"
      rpy="0 0.6929 -3.1416" />
    <parent
      link="Leg1_Coxa" />
    <child
      link="Leg1_Femur" />
    <axis
      xyz="0 1 0" />
    <limit
      lower="0"
      upper="0"
      effort="0"
      velocity="6.387" />
  </joint>
  <link
    name="Leg1_Tibia">
    <inertial>
      <origin
        xyz="-3.7858E-07 0.01266 0.096055"
        rpy="0 0 0" />
      <mass
        value="0.14511" />
      <inertia
        ixx="7.6445E-05"
        ixy="8.5435E-10"
        ixz="5.8161E-10"
        iyy="7.5405E-05"
        iyz="-9.6809E-07"
        izz="2.6542E-05" />
    </inertial>
    <visual>
      <origin
        xyz="0 0 0"
        rpy="0 0 0" />
      <geometry>
        <mesh
          filename="package://wwww_urdf/meshes/Leg1_Tibia.STL" />
      </geometry>
      <material
        name="">
        <color
          rgba="0.79216 0.81961 0.93333 1" />
      </material>
    </visual>
    <collision>
      <origin
        xyz="0 0 0"
        rpy="0 0 0" />
      <geometry>
        <mesh
          filename="package://wwww_urdf/meshes/Leg1_Tibia.STL" />
      </geometry>
    </collision>
  </link>
  <joint
    name="Leg1_joint3"
    type="revolute">
    <origin
      xyz="-0.11184 0 -0.064289"
      rpy="0 0.77158 3.1416" />
    <parent
      link="Leg1_Femur" />
    <child
      link="Leg1_Tibia" />
    <axis
      xyz="0 1 0" />
    <limit
      lower="0"
      upper="0"
      effort="0"
      velocity="6.387" />
  </joint>
  <link
    name="Leg1_Wheel">
    <inertial>
      <origin
        xyz="1.0949E-07 0.04477 -1.4969E-07"
        rpy="0 0 0" />
      <mass
        value="0.21062" />
      <inertia
        ixx="0.00034853"
        ixy="1.2204E-11"
        ixz="-2.3337E-09"
        iyy="0.00064443"
        iyz="1.7494E-12"
        izz="0.00034854" />
    </inertial>
    <visual>
      <origin
        xyz="0 0 0"
        rpy="0 0 0" />
      <geometry>
        <mesh
          filename="package://wwww_urdf/meshes/Leg1_Wheel.STL" />
      </geometry>
      <material
        name="">
        <color
          rgba="0.79216 0.81961 0.93333 1" />
      </material>
    </visual>
    <collision>
      <origin
        xyz="0 0 0"
        rpy="0 0 0" />
      <geometry>
        <mesh
          filename="package://wwww_urdf/meshes/Leg1_Wheel.STL" />
      </geometry>
    </collision>
  </link>
  <joint
    name="Leg1_joint4"
    type="continuous">
    <origin
      xyz="0 0 0.15718"
      rpy="-3.1416 0.19153 -3.1416" />
    <parent
      link="Leg1_Tibia" />
    <child
      link="Leg1_Wheel" />
    <axis
      xyz="0 1 0" />
    <limit
      effort="0"
      velocity="6.387" />
  </joint>
  <link
    name="leg2_coxa">
    <inertial>
      <origin
        xyz="0.029251 -0.00033242 0.035561"
        rpy="0 0 0" />
      <mass
        value="0.10502" />
      <inertia
        ixx="5.0395E-05"
        ixy="1.3471E-09"
        ixz="8.0078E-08"
        iyy="5.7752E-05"
        iyz="4.1974E-10"
        izz="3.5542E-05" />
    </inertial>
    <visual>
      <origin
        xyz="0 0 0"
        rpy="0 0 0" />
      <geometry>
        <mesh
          filename="package://wwww_urdf/meshes/leg2_coxa.STL" />
      </geometry>
      <material
        name="">
        <color
          rgba="0.79216 0.81961 0.93333 1" />
      </material>
    </visual>
    <collision>
      <origin
        xyz="0 0 0"
        rpy="0 0 0" />
      <geometry>
        <mesh
          filename="package://wwww_urdf/meshes/leg2_coxa.STL" />
      </geometry>
    </collision>
  </link>
  <joint
    name="leg2_joint1"
    type="revolute">
    <origin
      xyz="-0.019618 -0.24008 0.10529"
      rpy="-1.5834 1.1664 3.1279" />
    <parent
      link="base_link" />
    <child
      link="leg2_coxa" />
    <axis
      xyz="0.0053918 0 -0.99999" />
    <limit
      lower="0"
      upper="0"
      effort="0"
      velocity="6.387" />
  </joint>
  <link
    name="leg2_femur">
    <inertial>
      <origin
        xyz="-0.05592 0.0006271 -0.032144"
        rpy="0 0 0" />
      <mass
        value="0.094729" />
      <inertia
        ixx="6.9097E-05"
        ixy="-8.1609E-10"
        ixz="-5.3933E-06"
        iyy="5.7513E-05"
        iyz="-4.691E-10"
        izz="7.5379E-05" />
    </inertial>
    <visual>
      <origin
        xyz="0 0 0"
        rpy="0 0 0" />
      <geometry>
        <mesh
          filename="package://wwww_urdf/meshes/leg2_femur.STL" />
      </geometry>
      <material
        name="">
        <color
          rgba="0.79216 0.81961 0.93333 1" />
      </material>
    </visual>
    <collision>
      <origin
        xyz="0 0 0"
        rpy="0 0 0" />
      <geometry>
        <mesh
          filename="package://wwww_urdf/meshes/leg2_femur.STL" />
      </geometry>
    </collision>
  </link>
  <joint
    name="leg2_joint2"
    type="revolute">
    <origin
      xyz="0.064357 0 0.035898"
      rpy="0 0.49856 -3.1416" />
    <parent
      link="leg2_coxa" />
    <child
      link="leg2_femur" />
    <axis
      xyz="0 1 0" />
    <limit
      lower="0"
      upper="0"
      effort="0"
      velocity="6.387" />
  </joint>
  <link
    name="leg2_tibia">
    <inertial>
      <origin
        xyz="-2.78080573616613E-07 -0.0146865130682264 0.0960374243230176"
        rpy="0 0 0" />
      <mass
        value="0.14510633661613" />
      <inertia
        ixx="7.64420774286525E-05"
        ixy="8.85209131172503E-10"
        ixz="5.13427213827048E-10"
        iyy="7.54022852996233E-05"
        iyz="9.70624434444233E-07"
        izz="2.65420037717423E-05" />
    </inertial>
    <visual>
      <origin
        xyz="0 0 0"
        rpy="0 0 0" />
      <geometry>
        <mesh
          filename="package://wwww_urdf/meshes/leg2_tibia.STL" />
      </geometry>
      <material
        name="">
        <color
          rgba="0.792156862745098 0.819607843137255 0.933333333333333 1" />
      </material>
    </visual>
    <collision>
      <origin
        xyz="0 0 0"
        rpy="0 0 0" />
      <geometry>
        <mesh
          filename="package://wwww_urdf/meshes/leg2_tibia.STL" />
      </geometry>
    </collision>
  </link>
  <joint
    name="leg2_joint3"
    type="revolute">
    <origin
      xyz="-0.11184 0 -0.064289"
      rpy="0 0.72017 3.1416" />
    <parent
      link="leg2_femur" />
    <child
      link="leg2_tibia" />
    <axis
      xyz="0 1 0" />
    <limit
      lower="0"
      upper="0"
      effort="0"
      velocity="6.387" />
  </joint>
  <link
    name="leg2_wheel">
    <inertial>
      <origin
        xyz="1.09488726252049E-07 0.0474753205951267 -1.49688081263477E-07"
        rpy="0 0 0" />
      <mass
        value="0.210619497382952" />
      <inertia
        ixx="0.000348533984217759"
        ixy="1.22043417573853E-11"
        ixz="-2.333744828402E-09"
        iyy="0.000644434260231493"
        iyz="1.74937015496473E-12"
        izz="0.000348535390625117" />
    </inertial>
    <visual>
      <origin
        xyz="0 0 0"
        rpy="0 0 0" />
      <geometry>
        <mesh
          filename="package://wwww_urdf/meshes/leg2_wheel.STL" />
      </geometry>
      <material
        name="">
        <color
          rgba="0.792156862745098 0.819607843137255 0.933333333333333 1" />
      </material>
    </visual>
    <collision>
      <origin
        xyz="0 0 0"
        rpy="0 0 0" />
      <geometry>
        <mesh
          filename="package://wwww_urdf/meshes/leg2_wheel.STL" />
      </geometry>
    </collision>
  </link>
  <joint
    name="leg2_joint4"
    type="continuous">
    <origin
      xyz="0 0 0.15714"
      rpy="0 -0.041232 -3.1416" />
    <parent
      link="leg2_tibia" />
    <child
      link="leg2_wheel" />
    <axis
      xyz="0 1 0" />
    <limit
      effort="0"
      velocity="6.387" />
  </joint>
  <link
    name="leg3_coxa">
    <inertial>
      <origin
        xyz="0.0292513996308771 -0.0003324231188013 0.0355608456173721"
        rpy="0 0 0" />
      <mass
        value="0.105020719575034" />
      <inertia
        ixx="5.03953325193394E-05"
        ixy="1.34723899429193E-09"
        ixz="8.00773744363248E-08"
        iyy="5.77523241600365E-05"
        iyz="4.16781309827059E-10"
        izz="3.55419030510688E-05" />
    </inertial>
    <visual>
      <origin
        xyz="0 0 0"
        rpy="0 0 0" />
      <geometry>
        <mesh
          filename="package://wwww_urdf/meshes/leg3_coxa.STL" />
      </geometry>
      <material
        name="">
        <color
          rgba="0.792156862745098 0.819607843137255 0.933333333333333 1" />
      </material>
    </visual>
    <collision>
      <origin
        xyz="0 0 0"
        rpy="0 0 0" />
      <geometry>
        <mesh
          filename="package://wwww_urdf/meshes/leg3_coxa.STL" />
      </geometry>
    </collision>
  </link>
  <joint
    name="leg3_joint1"
    type="revolute">
    <origin
      xyz="0.20894 -0.24008 0.010233"
      rpy="-1.5917 1.3178 3.1201" />
    <parent
      link="base_link" />
    <child
      link="leg3_coxa" />
    <axis
      xyz="0.0053918 0 -0.99999" />
    <limit
      lower="0"
      upper="0"
      effort="0"
      velocity="6.387" />
  </joint>
  <link
    name="leg3_femur">
    <inertial>
      <origin
        xyz="-0.055919550106895 0.000627100491342014 -0.0321442665488382"
        rpy="0 0 0" />
      <mass
        value="0.0947288668425732" />
      <inertia
        ixx="6.90968708827936E-05"
        ixy="-8.16567904013499E-10"
        ixz="-5.3933262144797E-06"
        iyy="5.75125911480373E-05"
        iyz="-4.69281960965394E-10"
        izz="7.53790877435464E-05" />
    </inertial>
    <visual>
      <origin
        xyz="0 0 0"
        rpy="0 0 0" />
      <geometry>
        <mesh
          filename="package://wwww_urdf/meshes/leg3_femur.STL" />
      </geometry>
      <material
        name="">
        <color
          rgba="0.792156862745098 0.819607843137255 0.933333333333333 1" />
      </material>
    </visual>
    <collision>
      <origin
        xyz="0 0 0"
        rpy="0 0 0" />
      <geometry>
        <mesh
          filename="package://wwww_urdf/meshes/leg3_femur.STL" />
      </geometry>
    </collision>
  </link>
  <joint
    name="leg3_joint2"
    type="revolute">
    <origin
      xyz="0.064357 0 0.035898"
      rpy="0 0.71604 -3.1416" />
    <parent
      link="leg3_coxa" />
    <child
      link="leg3_femur" />
    <axis
      xyz="0 1 0" />
    <limit
      lower="0"
      upper="0"
      effort="0"
      velocity="6.387" />
  </joint>
  <link
    name="leg3_tibia">
    <inertial>
      <origin
        xyz="-3.66491048259254E-07 0.0126604923617305 0.0960551852243208"
        rpy="0 0 0" />
      <mass
        value="0.145106487814879" />
      <inertia
        ixx="7.64422029785046E-05"
        ixy="8.15688244073343E-10"
        ixz="2.90678799955368E-10"
        iyy="7.54022430364416E-05"
        iyz="-9.6814971816964E-07"
        izz="2.6542094173945E-05" />
    </inertial>
    <visual>
      <origin
        xyz="0 0 0"
        rpy="0 0 0" />
      <geometry>
        <mesh
          filename="package://wwww_urdf/meshes/leg3_tibia.STL" />
      </geometry>
      <material
        name="">
        <color
          rgba="0.792156862745098 0.819607843137255 0.933333333333333 1" />
      </material>
    </visual>
    <collision>
      <origin
        xyz="0 0 0"
        rpy="0 0 0" />
      <geometry>
        <mesh
          filename="package://wwww_urdf/meshes/leg3_tibia.STL" />
      </geometry>
    </collision>
  </link>
  <joint
    name="leg3_joint3"
    type="revolute">
    <origin
      xyz="-0.11184 0 -0.064289"
      rpy="0 0.89221 3.1416" />
    <parent
      link="leg3_femur" />
    <child
      link="leg3_tibia" />
    <axis
      xyz="0 1 0" />
    <limit
      lower="0"
      upper="0"
      effort="0"
      velocity="6.387" />
  </joint>
  <link
    name="leg3_wheel">
    <inertial>
      <origin
        xyz="1.09488728791685E-07 0.0199225302720451 -1.49688085537836E-07"
        rpy="0 0 0" />
      <mass
        value="0.210619497382952" />
      <inertia
        ixx="0.000348533984217774"
        ixy="1.22043234261796E-11"
        ixz="-2.33374482142245E-09"
        iyy="0.00064443426023149"
        iyz="1.74931389701502E-12"
        izz="0.000348535390625134" />
    </inertial>
    <visual>
      <origin
        xyz="0 0 0"
        rpy="0 0 0" />
      <geometry>
        <mesh
          filename="package://wwww_urdf/meshes/leg3_wheel.STL" />
      </geometry>
      <material
        name="">
        <color
          rgba="0.792156862745098 0.819607843137255 0.933333333333333 1" />
      </material>
    </visual>
    <collision>
      <origin
        xyz="0 0 0"
        rpy="0 0 0" />
      <geometry>
        <mesh
          filename="package://wwww_urdf/meshes/leg3_wheel.STL" />
      </geometry>
    </collision>
  </link>
  <joint
    name="leg3_joint4"
    type="continuous">
    <origin
      xyz="0 0.024847 0.15718"
      rpy="0 0.0023316 0" />
    <parent
      link="leg3_tibia" />
    <child
      link="leg3_wheel" />
    <axis
      xyz="0 1 0" />
    <limit
      effort="0"
      velocity="6.387" />
  </joint>
  <link
    name="leg4_coxa">
    <inertial>
      <origin
        xyz="0.0292513977217899 -0.00033242200338765 0.0355608436629877"
        rpy="0 0 0" />
      <mass
        value="0.105020717573293" />
      <inertia
        ixx="5.0395328718975E-05"
        ixy="1.34597484588258E-09"
        ixz="8.00782900202859E-08"
        iyy="5.77523154211785E-05"
        iyz="4.21883189403258E-10"
        izz="3.55419003478377E-05" />
    </inertial>
    <visual>
      <origin
        xyz="0 0 0"
        rpy="0 0 0" />
      <geometry>
        <mesh
          filename="package://wwww_urdf/meshes/leg4_coxa.STL" />
      </geometry>
      <material
        name="">
        <color
          rgba="0.792156862745098 0.819607843137255 0.933333333333333 1" />
      </material>
    </visual>
    <collision>
      <origin
        xyz="0 0 0"
        rpy="0 0 0" />
      <geometry>
        <mesh
          filename="package://wwww_urdf/meshes/leg4_coxa.STL" />
      </geometry>
    </collision>
  </link>
  <joint
    name="leg4_joint1"
    type="revolute">
    <origin
      xyz="0.30399 -0.24008 0.23879"
      rpy="1.5631 -0.96174 0.0094248" />
    <parent
      link="base_link" />
    <child
      link="leg4_coxa" />
    <axis
      xyz="0.0053918 0 -0.99999" />
    <limit
      lower="0"
      upper="0"
      effort="0"
      velocity="6.387" />
  </joint>
  <link
    name="leg4_femur">
    <inertial>
      <origin
        xyz="-0.0559195496564505 0.000627100878783537 -0.0321442665639246"
        rpy="0 0 0" />
      <mass
        value="0.0947288614954202" />
      <inertia
        ixx="6.90968689878752E-05"
        ixy="-8.16753177157111E-10"
        ixz="-5.39332647724369E-06"
        iyy="5.75125911934856E-05"
        iyz="-4.69267039930771E-10"
        izz="7.53790877001172E-05" />
    </inertial>
    <visual>
      <origin
        xyz="0 0 0"
        rpy="0 0 0" />
      <geometry>
        <mesh
          filename="package://wwww_urdf/meshes/leg4_femur.STL" />
      </geometry>
      <material
        name="">
        <color
          rgba="0.792156862745098 0.819607843137255 0.933333333333333 1" />
      </material>
    </visual>
    <collision>
      <origin
        xyz="0 0 0"
        rpy="0 0 0" />
      <geometry>
        <mesh
          filename="package://wwww_urdf/meshes/leg4_femur.STL" />
      </geometry>
    </collision>
  </link>
  <joint
    name="leg4_joint2"
    type="revolute">
    <origin
      xyz="0.064357 0 0.035898"
      rpy="0 0.8434 3.1416" />
    <parent
      link="leg4_coxa" />
    <child
      link="leg4_femur" />
    <axis
      xyz="0 1 0" />
    <limit
      lower="0"
      upper="0"
      effort="0"
      velocity="6.387" />
  </joint>
  <link
    name="leg4_tibia">
    <inertial>
      <origin
        xyz="-3.10726320673638E-07 -0.0146863991543403 0.0960377287785421"
        rpy="0 0 0" />
      <mass
        value="0.145107716079444" />
      <inertia
        ixx="7.64450026319013E-05"
        ixy="8.28881132888596E-10"
        ixz="8.27958826362001E-10"
        iyy="7.54051367805572E-05"
        iyz="9.70826526337247E-07"
        izz="2.65421606834181E-05" />
    </inertial>
    <visual>
      <origin
        xyz="0 0 0"
        rpy="0 0 0" />
      <geometry>
        <mesh
          filename="package://wwww_urdf/meshes/leg4_tibia.STL" />
      </geometry>
      <material
        name="">
        <color
          rgba="0.792156862745098 0.819607843137255 0.933333333333333 1" />
      </material>
    </visual>
    <collision>
      <origin
        xyz="0 0 0"
        rpy="0 0 0" />
      <geometry>
        <mesh
          filename="package://wwww_urdf/meshes/leg4_tibia.STL" />
      </geometry>
    </collision>
  </link>
  <joint
    name="leg4_joint3"
    type="revolute">
    <origin
      xyz="-0.11184 0 -0.064289"
      rpy="0 0.91285 -3.1416" />
    <parent
      link="leg4_femur" />
    <child
      link="leg4_tibia" />
    <axis
      xyz="0 1 0" />
    <limit
      lower="0"
      upper="0"
      effort="0"
      velocity="6.387" />
  </joint>
  <link
    name="leg4_wheel">
    <inertial>
      <origin
        xyz="1.09488727528806E-07 0.0474753205951262 -1.4968808093041E-07"
        rpy="0 0 0" />
      <mass
        value="0.210619497382947" />
      <inertia
        ixx="0.000348533984217708"
        ixy="1.22043322734049E-11"
        ixz="-2.33374482343839E-09"
        iyy="0.00064443426023148"
        iyz="1.74936066019559E-12"
        izz="0.000348535390625061" />
    </inertial>
    <visual>
      <origin
        xyz="0 0 0"
        rpy="0 0 0" />
      <geometry>
        <mesh
          filename="package://wwww_urdf/meshes/leg4_wheel.STL" />
      </geometry>
      <material
        name="">
        <color
          rgba="0.792156862745098 0.819607843137255 0.933333333333333 1" />
      </material>
    </visual>
    <collision>
      <origin
        xyz="0 0 0"
        rpy="0 0 0" />
      <geometry>
        <mesh
          filename="package://wwww_urdf/meshes/leg4_wheel.STL" />
      </geometry>
    </collision>
  </link>
  <joint
    name="leg4_joint4"
    type="continuous">
    <origin
      xyz="0 0 0.15714"
      rpy="0 -0.052942 3.1416" />
    <parent
      link="leg4_tibia" />
    <child
      link="leg4_wheel" />
    <axis
      xyz="0 1 0" />
    <limit
      effort="0"
      velocity="6.387" />
  </joint>
</robot>