<?xml version="1.0" ?>
<robot name="PhantomX" xmlns:xacro="http://www.ros.org/wiki/xacro">

  <link name="base_link"/>

  <joint name="j_phantomx_attachment" type="fixed">
    <parent link="base_link"/>
    <child link="MP_BODY"/>
    <origin rpy="0 0 0" xyz="0 0 0"/>
  </joint>

  <link name="MP_BODY">
    <inertial>
      <origin xyz="0 0 0"/>
      <mass value="0.97559947"/>
      <inertia ixx="3.1081800" ixy="-0.25460189" ixz="2.0318174" iyy="6.3787776" iyz="0.16417863" izz="5.3316425"/>
    </inertial>
    <visual>
      <!--origin xyz="-0.0235 0 -0.03525" rpy="0 0 0" /-->
      <origin rpy="0 0 0" xyz="0 0 0"/>
      <geometry>
        <!--box size="0.102 0.109 0.106" /-->
        <mesh filename="package://moonbot_description/meshes_phantom/body.STL" scale="1 1 1"/>
      </geometry>
      <material name="Grey">
        <color rgba="0.20 0.20 0.2 1.0"/>
      </material>
    </visual>
    <collision>
      <origin rpy="0 0 0" xyz="0 0 0"/>
      <geometry>
        <mesh filename="package://moonbot_description/meshes_phantom/body_coll.STL" scale="1 1 1"/>
      </geometry>
    </collision>
  </link>

  <gazebo reference="MP_BODY">
    <material>Gazebo/Grey</material>
  </gazebo>

  <link name="c1_rf">
    <inertial>
      <origin rpy="0 0 0" xyz="0 -0.02633 0"/>
      <mass value="0.024357719"/>
      <inertia ixx="0.0051411124" ixy="-0.00057530255" ixz="-0.000024729049" iyy="0.0081915737" iyz="-0.000019223094" izz="0.0011379812"/>
    </inertial>
    <visual>
      <origin rpy="0 0 0" xyz="0 -0.0252 0"/>
      <geometry>
        <!--box size="0.045 0.022 0.0325" /-->
        <mesh filename="package://moonbot_description/meshes_phantom/connect.STL" scale="1 1 1"/>
      </geometry>
      <material name="Grey">
        <color rgba="0.20 0.20 0.20 1.0"/>
      </material>
    </visual>
    <collision>
      <origin rpy="0 0 0" xyz="0 -0.02633 0"/>
      <geometry>
        <mesh filename="package://moonbot_description/meshes_phantom/connect_coll.STL" scale="1 1 1"/>
      </geometry>
    </collision>
  </link>

  <link name="c2_rf">
    <inertial>
      <origin rpy="0 0 0" xyz="0 -0.02633 0"/>
      <mass value="0.024357719"/>
      <inertia ixx="0.0051411124" ixy="-0.00057530255" ixz="-0.000024729049" iyy="0.0081915737" iyz="-0.000019223094" izz="0.0011379812"/>
    </inertial>
    <visual>
      <origin rpy="0 0 0" xyz="0 -0.0252 0"/>
      <geometry>
        <!--box size="0.045 0.022 0.0325" /-->
        <mesh filename="package://moonbot_description/meshes_phantom/connect.STL" scale="1 1 1"/>
      </geometry>
      <material name="Grey">
        <color rgba="0.20 0.20 0.20 1.0"/>
      </material>
    </visual>
    <collision>
      <origin rpy="0 0 0" xyz="0 -0.02633 0"/>
      <geometry>
        <mesh filename="package://moonbot_description/meshes_phantom/connect_coll.STL" scale="1 1 1"/>
      </geometry>
    </collision>
  </link>

  <link name="thigh_rf">
    <inertial>
      <origin rpy="0 0 0" xyz="0 0 0"/>
      <mass value="0.024357719"/>
      <inertia ixx="0.0051411124" ixy="-0.00057530255" ixz="-0.000024729049" iyy="0.0081915737" iyz="-0.000019223094" izz="0.0011379812"/>
    </inertial>
    <visual>
      <origin rpy="0 0 0" xyz="0 0 0"/>
      <geometry>
        <!--box size="0.045 0.022 0.0325" /-->
        <mesh filename="package://moonbot_description/meshes_phantom/thigh_l.STL" scale="1 1 1"/>
      </geometry>
      <material name="Grey">
        <color rgba="0.20 0.20 0.20 1.0"/>
      </material>
    </visual>
    <collision>
      <origin rpy="0 0 0" xyz="0 0 0"/>
      <geometry>
        <mesh filename="package://moonbot_description/meshes_phantom/thigh_l_coll.STL" scale="1 1 1"/>
      </geometry>
    </collision>
  </link>

  <link name="tibia_rf">
    <inertial>
      <origin rpy="0 0 0" xyz="0 0 0"/>
      <mass value="0.024357719"/>
      <inertia ixx="0.0051411124" ixy="-0.00057530255" ixz="-0.000024729049" iyy="0.0081915737" iyz="-0.000019223094" izz="0.0011379812"/>
    </inertial>
    <visual>
      <origin rpy="0 0 0" xyz="0 0 0"/>
      <geometry>
        <!--box size="0.045 0.022 0.0325" /-->
        <mesh filename="package://moonbot_description/meshes_phantom/tibia_l.STL" scale="1 1 1"/>
      </geometry>
      <material name="Grey">
        <color rgba="0.20 0.20 0.20 1.0"/>
      </material>
    </visual>
    <collision>
      <origin rpy="0 0 0" xyz="0 0 0"/>
      <geometry>
        <mesh filename="package://moonbot_description/meshes_phantom/tibia_l_coll.STL" scale="1 1 1"/>
      </geometry>
      <surface>
        <friction>
          <ode>
            <mu>0.01</mu>
            <mu2>0.01</mu2>
          </ode>
        </friction>
      </surface>
    </collision>
  </link>

  <joint name="j_c1_rf" type="revolute">
    <parent link="MP_BODY"/>
    <child link="c1_rf"/>
    <origin rpy="0 4.7123 0.7853981633974483" xyz="0.1248 -0.06164  0.001116"/>
    <axis xyz="1 0 0"/>
    <limit effort="2.8" lower="-2.6179939" upper="2.6179939" velocity="5.6548668"/>
  </joint>

  <joint name="j_c2_rf" type="fixed">
    <parent link="c1_rf"/>
    <child link="c2_rf"/>
    <origin rpy="0 1.5704 3.14159" xyz="0 -0.054 0"/>
  </joint>

  <joint name="j_thigh_rf" type="revolute">
    <parent link="c2_rf"/>
    <child link="thigh_rf"/>
    <!--origin xyz="0 0 0" rpy=" 0 3.14159 3.14159" /-->
    <origin rpy="3.14159 0  0" xyz="0 0 0"/>
    <axis xyz="1 0 0"/>
    <limit effort="2.8" lower="-2.6179939" upper="2.6179939" velocity="5.6548668"/>
  </joint>

  <joint name="j_tibia_rf" type="revolute">
    <parent link="thigh_rf"/>
    <child link="tibia_rf"/>
    <origin rpy="-1.5707 0 3.14159" xyz="0 -0.0645 -0.0145"/>
    <axis xyz="1 0 0"/>
    <limit effort="2.8" lower="-2.6179939" upper="2.6179939" velocity="5.6548668"/>
  </joint>

  <gazebo reference="c1_rf">
    <material>Gazebo/Grey</material>
  </gazebo>
  <gazebo reference="c2_rf">
    <material>Gazebo/Grey</material>
  </gazebo>
  <gazebo reference="thigh_rf">
    <material>Gazebo/Grey</material>
  </gazebo>
  <gazebo reference="tibia_rf">
    <material>Gazebo/Grey</material>
  </gazebo>

  <link name="c1_rr">
    <inertial>
      <origin rpy="0 0 0" xyz="0 -0.02633 0"/>
      <mass value="0.024357719"/>
      <inertia ixx="0.0051411124" ixy="-0.00057530255" ixz="-0.000024729049" iyy="0.0081915737" iyz="-0.000019223094" izz="0.0011379812"/>
    </inertial>
    <visual>
      <origin rpy="0 0 0" xyz="0 -0.0252 0"/>
      <geometry>
        <!--box size="0.045 0.022 0.0325" /-->
        <mesh filename="package://moonbot_description/meshes_phantom/connect.STL" scale="1 1 1"/>
      </geometry>
      <material name="Grey">
        <color rgba="0.20 0.20 0.20 1.0"/>
      </material>
    </visual>
    <collision>
      <origin rpy="0 0 0" xyz="0 -0.02633 0"/>
      <geometry>
        <mesh filename="package://moonbot_description/meshes_phantom/connect_coll.STL" scale="1 1 1"/>
      </geometry>
    </collision>
  </link>

  <link name="c2_rr">
    <inertial>
      <origin rpy="0 0 0" xyz="0 -0.02633 0"/>
      <mass value="0.024357719"/>
      <inertia ixx="0.0051411124" ixy="-0.00057530255" ixz="-0.000024729049" iyy="0.0081915737" iyz="-0.000019223094" izz="0.0011379812"/>
    </inertial>
    <visual>
      <origin rpy="0 0 0" xyz="0 -0.0252 0"/>
      <geometry>
        <!--box size="0.045 0.022 0.0325" /-->
        <mesh filename="package://moonbot_description/meshes_phantom/connect.STL" scale="1 1 1"/>
      </geometry>
      <material name="Grey">
        <color rgba="0.20 0.20 0.20 1.0"/>
      </material>
    </visual>
    <collision>
      <origin rpy="0 0 0" xyz="0 -0.02633 0"/>
      <geometry>
        <mesh filename="package://moonbot_description/meshes_phantom/connect_coll.STL" scale="1 1 1"/>
      </geometry>
    </collision>
  </link>
  <link name="thigh_rr">
    <inertial>
      <origin rpy="0 0 0" xyz="0 0 0"/>
      <mass value="0.024357719"/>
      <inertia ixx="0.0051411124" ixy="-0.00057530255" ixz="-0.000024729049" iyy="0.0081915737" iyz="-0.000019223094" izz="0.0011379812"/>
    </inertial>
    <visual>
      <origin rpy="0 0 0" xyz="0 0 0"/>
      <geometry>
        <!--box size="0.045 0.022 0.0325" /-->
        <mesh filename="package://moonbot_description/meshes_phantom/thigh_l.STL" scale="1 1 1"/>
      </geometry>
      <material name="Grey">
        <color rgba="0.20 0.20 0.20 1.0"/>
      </material>
    </visual>
    <collision>
      <origin rpy="0 0 0" xyz="0 0 0"/>
      <geometry>
        <mesh filename="package://moonbot_description/meshes_phantom/thigh_l_coll.STL" scale="1 1 1"/>
      </geometry>
    </collision>
  </link>
  <link name="tibia_rr">
    <inertial>
      <origin rpy="0 0 0" xyz="0 0 0"/>
      <mass value="0.024357719"/>
      <inertia ixx="0.0051411124" ixy="-0.00057530255" ixz="-0.000024729049" iyy="0.0081915737" iyz="-0.000019223094" izz="0.0011379812"/>
    </inertial>
    <visual>
      <origin rpy="0 0 0" xyz="0 0 0"/>
      <geometry>
        <!--box size="0.045 0.022 0.0325" /-->
        <mesh filename="package://moonbot_description/meshes_phantom/tibia_l.STL" scale="1 1 1"/>
      </geometry>
      <material name="Grey">
        <color rgba="0.20 0.20 0.20 1.0"/>
      </material>
    </visual>
    <collision>
      <origin rpy="0 0 0" xyz="0 0 0"/>
      <geometry>
        <mesh filename="package://moonbot_description/meshes_phantom/tibia_l_coll.STL" scale="1 1 1"/>
      </geometry>
      <surface>
        <friction>
          <ode>
            <mu>0.01</mu>
            <mu2>0.01</mu2>
          </ode>
        </friction>
      </surface>
    </collision>
  </link>
  <joint name="j_c1_rr" type="revolute">
    <parent link="MP_BODY"/>
    <child link="c1_rr"/>
    <origin rpy="0 4.7123 -0.7853981633974483" xyz="-0.1248 -0.06164  0.001116"/>
    <axis xyz="1 0 0"/>
    <limit effort="2.8" lower="-2.6179939" upper="2.6179939" velocity="5.6548668"/>
  </joint>
  <joint name="j_c2_rr" type="fixed">
    <parent link="c1_rr"/>
    <child link="c2_rr"/>
    <origin rpy="0 1.5704 3.14159" xyz="0 -0.054 0"/>
  </joint>
  <joint name="j_thigh_rr" type="revolute">
    <parent link="c2_rr"/>
    <child link="thigh_rr"/>
    <!--origin xyz="0 0 0" rpy=" 0 3.14159 3.14159" /-->
    <origin rpy="3.14159 0  0" xyz="0 0 0"/>
    <axis xyz="1 0 0"/>
    <limit effort="2.8" lower="-2.6179939" upper="2.6179939" velocity="5.6548668"/>
  </joint>
  <joint name="j_tibia_rr" type="revolute">
    <parent link="thigh_rr"/>
    <child link="tibia_rr"/>
    <origin rpy="-1.5707 0 3.14159" xyz="0 -0.0645 -0.0145"/>
    <axis xyz="1 0 0"/>
    <limit effort="2.8" lower="-2.6179939" upper="2.6179939" velocity="5.6548668"/>
  </joint>

  <gazebo reference="c1_rr">
    <material>Gazebo/Grey</material>
  </gazebo>
  <gazebo reference="c2_rr">
    <material>Gazebo/Grey</material>
  </gazebo>
  <gazebo reference="thigh_rr">
    <material>Gazebo/Grey</material>
  </gazebo>
  <gazebo reference="tibia_rr">
    <material>Gazebo/Grey</material>
  </gazebo>
  <link name="c1_lf">
    <inertial>
      <origin rpy="0 0 0" xyz="0 -0.02633 0"/>
      <mass value="0.024357719"/>
      <inertia ixx="0.0051411124" ixy="-0.00057530255" ixz="-0.000024729049" iyy="0.0081915737" iyz="-0.000019223094" izz="0.0011379812"/>
    </inertial>
    <visual>
      <origin rpy="0 0 0" xyz="0 -0.0252 0"/>
      <geometry>
        <!--box size="0.045 0.022 0.0325" /-->
        <mesh filename="package://moonbot_description/meshes_phantom/connect.STL" scale="1 1 1"/>
      </geometry>
      <material name="Grey">
        <color rgba="0.20 0.20 0.20 1.0"/>
      </material>
    </visual>
    <collision>
      <origin rpy="0 0 0" xyz="0 -0.02633 0"/>
      <geometry>
        <mesh filename="package://moonbot_description/meshes_phantom/connect_coll.STL" scale="1 1 1"/>
      </geometry>
    </collision>
  </link>
  <link name="c2_lf">
    <inertial>
      <origin rpy="0 0 0" xyz="0 -0.02633 0"/>
      <mass value="0.024357719"/>
      <inertia ixx="0.0051411124" ixy="-0.00057530255" ixz="-0.000024729049" iyy="0.0081915737" iyz="-0.000019223094" izz="0.0011379812"/>
    </inertial>
    <visual>
      <origin rpy="0 0 0" xyz="0 -0.0252 0"/>
      <geometry>
        <!--box size="0.045 0.022 0.0325" /-->
        <mesh filename="package://moonbot_description/meshes_phantom/connect.STL" scale="1 1 1"/>
      </geometry>
      <material name="Grey">
        <color rgba="0.20 0.20 0.20 1.0"/>
      </material>
    </visual>
    <collision>
      <origin rpy="0 0 0" xyz="0 -0.02633 0"/>
      <geometry>
        <mesh filename="package://moonbot_description/meshes_phantom/connect_coll.STL" scale="1 1 1"/>
      </geometry>
    </collision>
  </link>
  <link name="thigh_lf">
    <inertial>
      <origin rpy="0 0 0" xyz="0 0 0"/>
      <mass value="0.024357719"/>
      <inertia ixx="0.0051411124" ixy="-0.00057530255" ixz="-0.000024729049" iyy="0.0081915737" iyz="-0.000019223094" izz="0.0011379812"/>
    </inertial>
    <visual>
      <origin rpy="0 0 0" xyz="0 0 0"/>
      <geometry>
        <!--box size="0.045 0.022 0.0325" /-->
        <mesh filename="package://moonbot_description/meshes_phantom/thigh_l.STL" scale="1 1 1"/>
      </geometry>
      <material name="Grey">
        <color rgba="0.20 0.20 0.20 1.0"/>
      </material>
    </visual>
    <collision>
      <origin rpy="0 0 0" xyz="0 0 0"/>
      <geometry>
        <mesh filename="package://moonbot_description/meshes_phantom/thigh_l_coll.STL" scale="1 1 1"/>
      </geometry>
    </collision>
  </link>
  <link name="tibia_lf">
    <inertial>
      <origin rpy="0 0 0" xyz="0 0 0"/>
      <mass value="0.024357719"/>
      <inertia ixx="0.0051411124" ixy="-0.00057530255" ixz="-0.000024729049" iyy="0.0081915737" iyz="-0.000019223094" izz="0.0011379812"/>
    </inertial>
    <visual>
      <origin rpy="0 0 0" xyz="0 0 0"/>
      <geometry>
        <!--box size="0.045 0.022 0.0325" /-->
        <mesh filename="package://moonbot_description/meshes_phantom/tibia_l.STL" scale="1 1 1"/>
      </geometry>
      <material name="Grey">
        <color rgba="0.20 0.20 0.20 1.0"/>
      </material>
    </visual>
    <collision>
      <origin rpy="0 0 0" xyz="0 0 0"/>
      <geometry>
        <mesh filename="package://moonbot_description/meshes_phantom/tibia_l_coll.STL" scale="1 1 1"/>
      </geometry>
      <surface>
        <friction>
          <ode>
            <mu>0.01</mu>
            <mu2>0.01</mu2>
          </ode>
        </friction>
      </surface>
    </collision>
  </link>
  <joint name="j_c1_lf" type="revolute">
    <parent link="MP_BODY"/>
    <child link="c1_lf"/>
    <origin rpy="0 4.7123 2.356194490192345" xyz="0.1248 0.06164  0.001116"/>
    <axis xyz="1 0 0"/>
    <limit effort="2.8" lower="-2.6179939" upper="2.6179939" velocity="5.6548668"/>
  </joint>
  <joint name="j_c2_lf" type="fixed">
    <parent link="c1_lf"/>
    <child link="c2_lf"/>
    <origin rpy="0 1.5704 3.14159" xyz="0 -0.054 0"/>
  </joint>
  <joint name="j_thigh_lf" type="revolute">
    <parent link="c2_lf"/>
    <child link="thigh_lf"/>
    <!--origin xyz="0 0 0" rpy=" 0 3.14159 3.14159" /-->
    <origin rpy="3.14159 0  0" xyz="0 0 0"/>
    <axis xyz="1 0 0"/>
    <limit effort="2.8" lower="-2.6179939" upper="2.6179939" velocity="5.6548668"/>
  </joint>
  <joint name="j_tibia_lf" type="revolute">
    <parent link="thigh_lf"/>
    <child link="tibia_lf"/>
    <origin rpy="-1.5707 0 3.14159" xyz="0 -0.0645 -0.0145"/>
    <axis xyz="1 0 0"/>
    <limit effort="2.8" lower="-2.6179939" upper="2.6179939" velocity="5.6548668"/>
  </joint>

  <gazebo reference="c1_lf">
    <material>Gazebo/Grey</material>
  </gazebo>
  <gazebo reference="c2_lf">
    <material>Gazebo/Grey</material>
  </gazebo>
  <gazebo reference="thigh_lf">
    <material>Gazebo/Grey</material>
  </gazebo>
  <gazebo reference="tibia_lf">
    <material>Gazebo/Grey</material>
  </gazebo>
  

  <link name="c1_lr">
    <inertial>
      <origin rpy="0 0 0" xyz="0 -0.02633 0"/>
      <mass value="0.024357719"/>
      <inertia ixx="0.0051411124" ixy="-0.00057530255" ixz="-0.000024729049" iyy="0.0081915737" iyz="-0.000019223094" izz="0.0011379812"/>
    </inertial>
    <visual>
      <origin rpy="0 0 0" xyz="0 -0.0252 0"/>
      <geometry>
        <!--box size="0.045 0.022 0.0325" /-->
        <mesh filename="package://moonbot_description/meshes_phantom/connect.STL" scale="1 1 1"/>
      </geometry>
      <material name="Grey">
        <color rgba="0.20 0.20 0.20 1.0"/>
      </material>
    </visual>
    <collision>
      <origin rpy="0 0 0" xyz="0 -0.02633 0"/>
      <geometry>
        <mesh filename="package://moonbot_description/meshes_phantom/connect_coll.STL" scale="1 1 1"/>
      </geometry>
    </collision>
  </link>
  <link name="c2_lr">
    <inertial>
      <origin rpy="0 0 0" xyz="0 -0.02633 0"/>
      <mass value="0.024357719"/>
      <inertia ixx="0.0051411124" ixy="-0.00057530255" ixz="-0.000024729049" iyy="0.0081915737" iyz="-0.000019223094" izz="0.0011379812"/>
    </inertial>
    <visual>
      <origin rpy="0 0 0" xyz="0 -0.0252 0"/>
      <geometry>
        <!--box size="0.045 0.022 0.0325" /-->
        <mesh filename="package://moonbot_description/meshes_phantom/connect.STL" scale="1 1 1"/>
      </geometry>
      <material name="Grey">
        <color rgba="0.20 0.20 0.20 1.0"/>
      </material>
    </visual>
    <collision>
      <origin rpy="0 0 0" xyz="0 -0.02633 0"/>
      <geometry>
        <mesh filename="package://moonbot_description/meshes_phantom/connect_coll.STL" scale="1 1 1"/>
      </geometry>
    </collision>
  </link>
  <link name="thigh_lr">
    <inertial>
      <origin rpy="0 0 0" xyz="0 0 0"/>
      <mass value="0.024357719"/>
      <inertia ixx="0.0051411124" ixy="-0.00057530255" ixz="-0.000024729049" iyy="0.0081915737" iyz="-0.000019223094" izz="0.0011379812"/>
    </inertial>
    <visual>
      <origin rpy="0 0 0" xyz="0 0 0"/>
      <geometry>
        <!--box size="0.045 0.022 0.0325" /-->
        <mesh filename="package://moonbot_description/meshes_phantom/thigh_l.STL" scale="1 1 1"/>
      </geometry>
      <material name="Grey">
        <color rgba="0.20 0.20 0.20 1.0"/>
      </material>
    </visual>
    <collision>
      <origin rpy="0 0 0" xyz="0 0 0"/>
      <geometry>
        <mesh filename="package://moonbot_description/meshes_phantom/thigh_l_coll.STL" scale="1 1 1"/>
      </geometry>
    </collision>
  </link>
  <link name="tibia_lr">
    <inertial>
      <origin rpy="0 0 0" xyz="0 0 0"/>
      <mass value="0.024357719"/>
      <inertia ixx="0.0051411124" ixy="-0.00057530255" ixz="-0.000024729049" iyy="0.0081915737" iyz="-0.000019223094" izz="0.0011379812"/>
    </inertial>
    <visual>
      <origin rpy="0 0 0" xyz="0 0 0"/>
      <geometry>
        <!--box size="0.045 0.022 0.0325" /-->
        <mesh filename="package://moonbot_description/meshes_phantom/tibia_l.STL" scale="1 1 1"/>
      </geometry>
      <material name="Grey">
        <color rgba="0.20 0.20 0.20 1.0"/>
      </material>
    </visual>
    <collision>
      <origin rpy="0 0 0" xyz="0 0 0"/>
      <geometry>
        <mesh filename="package://moonbot_description/meshes_phantom/tibia_l_coll.STL" scale="1 1 1"/>
      </geometry>
    </collision>
    <surface>
      <friction>
        <ode>
          <mu>0.01</mu>
          <mu2>0.01</mu2>
        </ode>
      </friction>
    </surface>
  </link>
  <joint name="j_c1_lr" type="revolute">
    <parent link="MP_BODY"/>
    <child link="c1_lr"/>
    <origin rpy="0 4.7123 3.9269908169872414" xyz="-0.1248 0.06164  0.001116"/>
    <axis xyz="1 0 0"/>
    <limit effort="2.8" lower="-2.6179939" upper="2.6179939" velocity="5.6548668"/>
  </joint>
  <joint name="j_c2_lr" type="fixed">
    <parent link="c1_lr"/>
    <child link="c2_lr"/>
    <origin rpy="0 1.5704 3.14159" xyz="0 -0.054 0"/>
  </joint>
  <joint name="j_thigh_lr" type="revolute">
    <parent link="c2_lr"/>
    <child link="thigh_lr"/>
    <!--origin xyz="0 0 0" rpy=" 0 3.14159 3.14159" /-->
    <origin rpy="3.14159 0  0" xyz="0 0 0"/>
    <axis xyz="1 0 0"/>
    <limit effort="2.8" lower="-2.6179939" upper="2.6179939" velocity="5.6548668"/>
  </joint>
  <joint name="j_tibia_lr" type="revolute">
    <parent link="thigh_lr"/>
    <child link="tibia_lr"/>
    <origin rpy="-1.5707 0 3.14159" xyz="0 -0.0645 -0.0145"/>
    <axis xyz="1 0 0"/>
    <limit effort="2.8" lower="-2.6179939" upper="2.6179939" velocity="5.6548668"/>
  </joint>
  

  <gazebo reference="c1_lr">
    <material>Gazebo/Grey</material>
  </gazebo>
  <gazebo reference="c2_lr">
    <material>Gazebo/Grey</material>
  </gazebo>
  <gazebo reference="thigh_lr">
    <material>Gazebo/Grey</material>
  </gazebo>
  <gazebo reference="tibia_lr">
    <material>Gazebo/Grey</material>
  </gazebo>

  <ros2_control name="MyRobotSystem" type="system">
    <hardware>
      <plugin>gazebo_ros2_control/GazeboSystem</plugin>
    </hardware>
    
    <joint name="j_c1_lf">
      <command_interface name="position">
        <param name="min">-2.6179939</param>
        <param name="max">2.6179939</param>
      </command_interface>
      <command_interface name="velocity">
        <param name="min">-5.6548668</param>
        <param name="max">5.6548668</param>
      </command_interface>
      <command_interface name="effort">
        <param name="min">-2.8</param>
        <param name="max">2.8</param>
      </command_interface>
      <state_interface name="position"/>
      <state_interface name="velocity"/>
      <state_interface name="effort"/>
    </joint>

    <joint name="j_c1_rf">
      <command_interface name="position">
        <param name="min">-2.6179939</param>
        <param name="max">2.6179939</param>
      </command_interface>
      <command_interface name="velocity">
        <param name="min">-5.6548668</param>
        <param name="max">5.6548668</param>
      </command_interface>
      <command_interface name="effort">
        <param name="min">-2.8</param>
        <param name="max">2.8</param>
      </command_interface>
      <state_interface name="position"/>
      <state_interface name="velocity"/>
      <state_interface name="effort"/>
    </joint>

    <joint name="j_c1_lr">
      <command_interface name="position">
        <param name="min">-2.6179939</param>
        <param name="max">2.6179939</param>
      </command_interface>
      <command_interface name="velocity">
        <param name="min">-5.6548668</param>
        <param name="max">5.6548668</param>
      </command_interface>
      <command_interface name="effort">
        <param name="min">-2.8</param>
        <param name="max">2.8</param>
      </command_interface>
      <state_interface name="position"/>
      <state_interface name="velocity"/>
      <state_interface name="effort"/>
    </joint>

    <joint name="j_c1_rr">
      <command_interface name="position">
        <param name="min">-2.6179939</param>
        <param name="max">2.6179939</param>
      </command_interface>
      <command_interface name="velocity">
        <param name="min">-5.6548668</param>
        <param name="max">5.6548668</param>
      </command_interface>
      <command_interface name="effort">
        <param name="min">-2.8</param>
        <param name="max">2.8</param>
      </command_interface>
      <state_interface name="position"/>
      <state_interface name="velocity"/>
      <state_interface name="effort"/>
    </joint>

    <joint name="j_thigh_lf">
      <command_interface name="position">
        <param name="min">-2.6179939</param>
        <param name="max">2.6179939</param>
      </command_interface>
      <command_interface name="velocity">
        <param name="min">-5.6548668</param>
        <param name="max">5.6548668</param>
      </command_interface>
      <command_interface name="effort">
        <param name="min">-2.8</param>
        <param name="max">2.8</param>
      </command_interface>
      <state_interface name="position"/>
      <state_interface name="velocity"/>
      <state_interface name="effort"/>
    </joint>

    <joint name="j_thigh_rf">
      <command_interface name="position">
        <param name="min">-2.6179939</param>
        <param name="max">2.6179939</param>
      </command_interface>
      <command_interface name="velocity">
        <param name="min">-5.6548668</param>
        <param name="max">5.6548668</param>
      </command_interface>
      <command_interface name="effort">
        <param name="min">-2.8</param>
        <param name="max">2.8</param>
      </command_interface>
      <state_interface name="position"/>
      <state_interface name="velocity"/>
      <state_interface name="effort"/>
    </joint>

    <joint name="j_thigh_lr">
      <command_interface name="position">
        <param name="min">-2.6179939</param>
        <param name="max">2.6179939</param>
      </command_interface>
      <command_interface name="velocity">
        <param name="min">-5.6548668</param>
        <param name="max">5.6548668</param>
      </command_interface>
      <command_interface name="effort">
        <param name="min">-2.8</param>
        <param name="max">2.8</param>
      </command_interface>
      <state_interface name="position"/>
      <state_interface name="velocity"/>
      <state_interface name="effort"/>
    </joint>

    <joint name="j_thigh_rr">
      <command_interface name="position">
        <param name="min">-2.6179939</param>
        <param name="max">2.6179939</param>
      </command_interface>
      <command_interface name="velocity">
        <param name="min">-5.6548668</param>
        <param name="max">5.6548668</param>
      </command_interface>
      <command_interface name="effort">
        <param name="min">-2.8</param>
        <param name="max">2.8</param>
      </command_interface>
      <state_interface name="position"/>
      <state_interface name="velocity"/>
      <state_interface name="effort"/>
    </joint>

    <joint name="j_tibia_lf">
      <command_interface name="position">
        <param name="min">-2.6179939</param>
        <param name="max">2.6179939</param>
      </command_interface>
      <command_interface name="velocity">
        <param name="min">-5.6548668</param>
        <param name="max">5.6548668</param>
      </command_interface>
      <command_interface name="effort">
        <param name="min">-2.8</param>
        <param name="max">2.8</param>
      </command_interface>
      <state_interface name="position"/>
      <state_interface name="velocity"/>
      <state_interface name="effort"/>
    </joint>

    <joint name="j_tibia_rf">
      <command_interface name="position">
        <param name="min">-2.6179939</param>
        <param name="max">2.6179939</param>
      </command_interface>
      <command_interface name="velocity">
        <param name="min">-5.6548668</param>
        <param name="max">5.6548668</param>
      </command_interface>
      <command_interface name="effort">
        <param name="min">-2.8</param>
        <param name="max">2.8</param>
      </command_interface>
      <state_interface name="position"/>
      <state_interface name="velocity"/>
      <state_interface name="effort"/>
    </joint>
    
    <joint name="j_tibia_lr">
      <command_interface name="position">
        <param name="min">-2.6179939</param>
        <param name="max">2.6179939</param>
      </command_interface>
      <command_interface name="velocity">
        <param name="min">-5.6548668</param>
        <param name="max">5.6548668</param>
      </command_interface>
      <command_interface name="effort">
        <param name="min">-2.8</param>
        <param name="max">2.8</param>
      </command_interface>
      <state_interface name="position"/>
      <state_interface name="velocity"/>
      <state_interface name="effort"/>
    </joint>

    <joint name="j_tibia_rr">
      <command_interface name="position">
        <param name="min">-2.6179939</param>
        <param name="max">2.6179939</param>
      </command_interface>
      <command_interface name="velocity">
        <param name="min">-5.6548668</param>
        <param name="max">5.6548668</param>
      </command_interface>
      <command_interface name="effort">
        <param name="min">-2.8</param>
        <param name="max">2.8</param>
      </command_interface>
      <state_interface name="position"/>
      <state_interface name="velocity"/>
      <state_interface name="effort"/>
    </joint>

  </ros2_control>

  <!-- Gazebo's ros2_control plugin  -->
  <gazebo>
    <plugin filename="libgazebo_ros2_control.so" name="gazebo_ros2_control">
      <!-- <robotNamespace>/phantomx</robotNamespace> -->
      <robot_sim_type>gazebo_ros2_control/GazeboSystem</robot_sim_type>
      <robot_param>robot_description</robot_param>
      <robot_param_node>robot_state_publisher_node</robot_param_node>
      <parameters>$(find moonbot_control)/config/phantom_config.yaml</parameters>
    </plugin>
  </gazebo>  

  <!-- <gazebo>
    <plugin name="gazebo_ros_joint_state_publisher" filename="libgazebo_ros_joint_state_publisher.so">
      <update_rate>20</update_rate>
      <joint_name>j_c1_lf</joint_name>
      <joint_name>j_c1_rf</joint_name>
      <joint_name>j_c1_lr</joint_name>
      <joint_name>j_c1_rr</joint_name>

      <joint_name>j_thigh_lf</joint_name>
      <joint_name>j_thigh_rf</joint_name>
      <joint_name>j_thigh_lr</joint_name>
      <joint_name>j_thigh_rr</joint_name>
      
      <joint_name>j_tibia_lf</joint_name>
      <joint_name>j_tibia_rf</joint_name>
      <joint_name>j_tibia_lr</joint_name>
      <joint_name>j_tibia_rr</joint_name>
    </plugin>
  </gazebo> 

 
  <gazebo>
    <plugin name="gazebo_ros_joint_pose_trajectory"
      filename="libgazebo_ros_joint_pose_trajectory.so">
      <update_rate>2</update_rate>
    </plugin>
  </gazebo> -->

</robot>